ERROR 2025-08-27 21:13:16,568 log 16352 14612 Internal Server Error: /api/auth/auth/login/
Traceback (most recent call last):
  File "C:\Users\ModernTech\.virtualenvs\evoting_system-M8NHDx1B\Lib\site-packages\django\core\handlers\exception.py", line 55, in inner
    response = get_response(request)
  File "C:\Users\ModernTech\.virtualenvs\evoting_system-M8NHDx1B\Lib\site-packages\django\core\handlers\base.py", line 220, in _get_response
    response = response.render()
  File "C:\Users\ModernTech\.virtualenvs\evoting_system-M8NHDx1B\Lib\site-packages\django\template\response.py", line 114, in render
    self.content = self.rendered_content
                   ^^^^^^^^^^^^^^^^^^^^^
  File "C:\Users\ModernTech\.virtualenvs\evoting_system-M8NHDx1B\Lib\site-packages\rest_framework\response.py", line 74, in rendered_content
    ret = renderer.render(self.data, accepted_media_type, context)
  File "C:\Users\ModernTech\.virtualenvs\evoting_system-M8NHDx1B\Lib\site-packages\rest_framework\renderers.py", line 731, in render
    context = self.get_context(data, accepted_media_type, renderer_context)
  File "C:\Users\ModernTech\.virtualenvs\evoting_system-M8NHDx1B\Lib\site-packages\rest_framework\renderers.py", line 662, in get_context
    raw_data_post_form = self.get_raw_data_form(data, view, 'POST', request)
  File "C:\Users\ModernTech\.virtualenvs\evoting_system-M8NHDx1B\Lib\site-packages\rest_framework\renderers.py", line 558, in get_raw_data_form
    serializer = view.get_serializer()
  File "C:\Users\ModernTech\.virtualenvs\evoting_system-M8NHDx1B\Lib\site-packages\rest_framework\generics.py", line 112, in get_serializer
    serializer_class = self.get_serializer_class()
  File "C:\Users\ModernTech\.virtualenvs\evoting_system-M8NHDx1B\Lib\site-packages\rest_framework\generics.py", line 126, in get_serializer_class
    assert self.serializer_class is not None, (
           ^^^^^^^^^^^^^^^^^^^^^^^^^^^^^^^^^
AssertionError: 'UserLoginView' should either include a `serializer_class` attribute, or override the `get_serializer_class()` method.
ERROR 2025-08-27 21:15:16,416 log 9108 12224 Internal Server Error: /api/auth/login/
Traceback (most recent call last):
  File "C:\Users\ModernTech\.virtualenvs\evoting_system-M8NHDx1B\Lib\site-packages\django\core\handlers\exception.py", line 55, in inner
    response = get_response(request)
  File "C:\Users\ModernTech\.virtualenvs\evoting_system-M8NHDx1B\Lib\site-packages\django\core\handlers\base.py", line 220, in _get_response
    response = response.render()
  File "C:\Users\ModernTech\.virtualenvs\evoting_system-M8NHDx1B\Lib\site-packages\django\template\response.py", line 114, in render
    self.content = self.rendered_content
                   ^^^^^^^^^^^^^^^^^^^^^
  File "C:\Users\ModernTech\.virtualenvs\evoting_system-M8NHDx1B\Lib\site-packages\rest_framework\response.py", line 74, in rendered_content
    ret = renderer.render(self.data, accepted_media_type, context)
  File "C:\Users\ModernTech\.virtualenvs\evoting_system-M8NHDx1B\Lib\site-packages\rest_framework\renderers.py", line 731, in render
    context = self.get_context(data, accepted_media_type, renderer_context)
  File "C:\Users\ModernTech\.virtualenvs\evoting_system-M8NHDx1B\Lib\site-packages\rest_framework\renderers.py", line 662, in get_context
    raw_data_post_form = self.get_raw_data_form(data, view, 'POST', request)
  File "C:\Users\ModernTech\.virtualenvs\evoting_system-M8NHDx1B\Lib\site-packages\rest_framework\renderers.py", line 558, in get_raw_data_form
    serializer = view.get_serializer()
  File "C:\Users\ModernTech\.virtualenvs\evoting_system-M8NHDx1B\Lib\site-packages\rest_framework\generics.py", line 112, in get_serializer
    serializer_class = self.get_serializer_class()
  File "C:\Users\ModernTech\.virtualenvs\evoting_system-M8NHDx1B\Lib\site-packages\rest_framework\generics.py", line 126, in get_serializer_class
    assert self.serializer_class is not None, (
           ^^^^^^^^^^^^^^^^^^^^^^^^^^^^^^^^^
AssertionError: 'UserLoginView' should either include a `serializer_class` attribute, or override the `get_serializer_class()` method.
ERROR 2025-08-29 09:19:31,195 log 8340 7204 Internal Server Error: /api/auth/voter_login/
Traceback (most recent call last):
  File "C:\Users\DELL\AppData\Local\Programs\Python\Python313\Lib\site-packages\django\core\handlers\exception.py", line 55, in inner
    response = get_response(request)
  File "C:\Users\DELL\AppData\Local\Programs\Python\Python313\Lib\site-packages\django\core\handlers\base.py", line 197, in _get_response
    response = wrapped_callback(request, *callback_args, **callback_kwargs)
  File "C:\Users\DELL\AppData\Local\Programs\Python\Python313\Lib\site-packages\django\views\decorators\csrf.py", line 65, in _view_wrapper
    return view_func(request, *args, **kwargs)
  File "C:\Users\DELL\AppData\Local\Programs\Python\Python313\Lib\site-packages\django\views\generic\base.py", line 105, in view
    return self.dispatch(request, *args, **kwargs)
           ~~~~~~~~~~~~~^^^^^^^^^^^^^^^^^^^^^^^^^^
  File "C:\Users\DELL\AppData\Local\Programs\Python\Python313\Lib\site-packages\rest_framework\views.py", line 515, in dispatch
    response = self.handle_exception(exc)
  File "C:\Users\DELL\AppData\Local\Programs\Python\Python313\Lib\site-packages\rest_framework\views.py", line 475, in handle_exception
    self.raise_uncaught_exception(exc)
    ~~~~~~~~~~~~~~~~~~~~~~~~~~~~~^^^^^
  File "C:\Users\DELL\AppData\Local\Programs\Python\Python313\Lib\site-packages\rest_framework\views.py", line 486, in raise_uncaught_exception
    raise exc
  File "C:\Users\DELL\AppData\Local\Programs\Python\Python313\Lib\site-packages\rest_framework\views.py", line 512, in dispatch
    response = handler(request, *args, **kwargs)
  File "C:\Users\DELL\Desktop\projects\offline_voting_system\backend\accounts\views.py", line 56, in post
    if not voter.election.is_ongoing:
           ^^^^^
UnboundLocalError: cannot access local variable 'voter' where it is not associated with a value
ERROR 2025-08-29 11:19:45,786 log 8340 4720 Internal Server Error: /api/auth/voter_login/
Traceback (most recent call last):
  File "C:\Users\DELL\AppData\Local\Programs\Python\Python313\Lib\site-packages\django\core\handlers\exception.py", line 55, in inner
    response = get_response(request)
  File "C:\Users\DELL\AppData\Local\Programs\Python\Python313\Lib\site-packages\django\core\handlers\base.py", line 197, in _get_response
    response = wrapped_callback(request, *callback_args, **callback_kwargs)
  File "C:\Users\DELL\AppData\Local\Programs\Python\Python313\Lib\site-packages\django\views\decorators\csrf.py", line 65, in _view_wrapper
    return view_func(request, *args, **kwargs)
  File "C:\Users\DELL\AppData\Local\Programs\Python\Python313\Lib\site-packages\django\views\generic\base.py", line 105, in view
    return self.dispatch(request, *args, **kwargs)
           ~~~~~~~~~~~~~^^^^^^^^^^^^^^^^^^^^^^^^^^
  File "C:\Users\DELL\AppData\Local\Programs\Python\Python313\Lib\site-packages\rest_framework\views.py", line 515, in dispatch
    response = self.handle_exception(exc)
  File "C:\Users\DELL\AppData\Local\Programs\Python\Python313\Lib\site-packages\rest_framework\views.py", line 475, in handle_exception
    self.raise_uncaught_exception(exc)
    ~~~~~~~~~~~~~~~~~~~~~~~~~~~~~^^^^^
  File "C:\Users\DELL\AppData\Local\Programs\Python\Python313\Lib\site-packages\rest_framework\views.py", line 486, in raise_uncaught_exception
    raise exc
  File "C:\Users\DELL\AppData\Local\Programs\Python\Python313\Lib\site-packages\rest_framework\views.py", line 512, in dispatch
    response = handler(request, *args, **kwargs)
  File "C:\Users\DELL\Desktop\projects\offline_voting_system\backend\accounts\views.py", line 56, in post
    if not voter.election.is_ongoing:
           ^^^^^
UnboundLocalError: cannot access local variable 'voter' where it is not associated with a value
ERROR 2025-08-29 11:21:35,159 log 8340 4720 Internal Server Error: /api/auth/voter_login/
Traceback (most recent call last):
  File "C:\Users\DELL\AppData\Local\Programs\Python\Python313\Lib\site-packages\django\core\handlers\exception.py", line 55, in inner
    response = get_response(request)
  File "C:\Users\DELL\AppData\Local\Programs\Python\Python313\Lib\site-packages\django\core\handlers\base.py", line 197, in _get_response
    response = wrapped_callback(request, *callback_args, **callback_kwargs)
  File "C:\Users\DELL\AppData\Local\Programs\Python\Python313\Lib\site-packages\django\views\decorators\csrf.py", line 65, in _view_wrapper
    return view_func(request, *args, **kwargs)
  File "C:\Users\DELL\AppData\Local\Programs\Python\Python313\Lib\site-packages\django\views\generic\base.py", line 105, in view
    return self.dispatch(request, *args, **kwargs)
           ~~~~~~~~~~~~~^^^^^^^^^^^^^^^^^^^^^^^^^^
  File "C:\Users\DELL\AppData\Local\Programs\Python\Python313\Lib\site-packages\rest_framework\views.py", line 515, in dispatch
    response = self.handle_exception(exc)
  File "C:\Users\DELL\AppData\Local\Programs\Python\Python313\Lib\site-packages\rest_framework\views.py", line 475, in handle_exception
    self.raise_uncaught_exception(exc)
    ~~~~~~~~~~~~~~~~~~~~~~~~~~~~~^^^^^
  File "C:\Users\DELL\AppData\Local\Programs\Python\Python313\Lib\site-packages\rest_framework\views.py", line 486, in raise_uncaught_exception
    raise exc
  File "C:\Users\DELL\AppData\Local\Programs\Python\Python313\Lib\site-packages\rest_framework\views.py", line 512, in dispatch
    response = handler(request, *args, **kwargs)
  File "C:\Users\DELL\Desktop\projects\offline_voting_system\backend\accounts\views.py", line 56, in post
    if not voter.election.is_ongoing:
           ^^^^^
UnboundLocalError: cannot access local variable 'voter' where it is not associated with a value
ERROR 2025-08-29 11:21:48,756 log 8340 4720 Internal Server Error: /api/auth/voter_login/
Traceback (most recent call last):
  File "C:\Users\DELL\AppData\Local\Programs\Python\Python313\Lib\site-packages\django\core\handlers\exception.py", line 55, in inner
    response = get_response(request)
  File "C:\Users\DELL\AppData\Local\Programs\Python\Python313\Lib\site-packages\django\core\handlers\base.py", line 197, in _get_response
    response = wrapped_callback(request, *callback_args, **callback_kwargs)
  File "C:\Users\DELL\AppData\Local\Programs\Python\Python313\Lib\site-packages\django\views\decorators\csrf.py", line 65, in _view_wrapper
    return view_func(request, *args, **kwargs)
  File "C:\Users\DELL\AppData\Local\Programs\Python\Python313\Lib\site-packages\django\views\generic\base.py", line 105, in view
    return self.dispatch(request, *args, **kwargs)
           ~~~~~~~~~~~~~^^^^^^^^^^^^^^^^^^^^^^^^^^
  File "C:\Users\DELL\AppData\Local\Programs\Python\Python313\Lib\site-packages\rest_framework\views.py", line 515, in dispatch
    response = self.handle_exception(exc)
  File "C:\Users\DELL\AppData\Local\Programs\Python\Python313\Lib\site-packages\rest_framework\views.py", line 475, in handle_exception
    self.raise_uncaught_exception(exc)
    ~~~~~~~~~~~~~~~~~~~~~~~~~~~~~^^^^^
  File "C:\Users\DELL\AppData\Local\Programs\Python\Python313\Lib\site-packages\rest_framework\views.py", line 486, in raise_uncaught_exception
    raise exc
  File "C:\Users\DELL\AppData\Local\Programs\Python\Python313\Lib\site-packages\rest_framework\views.py", line 512, in dispatch
    response = handler(request, *args, **kwargs)
  File "C:\Users\DELL\Desktop\projects\offline_voting_system\backend\accounts\views.py", line 56, in post
    if not voter.election.is_ongoing:
           ^^^^^
UnboundLocalError: cannot access local variable 'voter' where it is not associated with a value
ERROR 2025-08-29 11:27:01,253 log 8340 16136 Internal Server Error: /api/auth/voter_login/
Traceback (most recent call last):
  File "C:\Users\DELL\AppData\Local\Programs\Python\Python313\Lib\site-packages\django\core\handlers\exception.py", line 55, in inner
    response = get_response(request)
  File "C:\Users\DELL\AppData\Local\Programs\Python\Python313\Lib\site-packages\django\core\handlers\base.py", line 197, in _get_response
    response = wrapped_callback(request, *callback_args, **callback_kwargs)
  File "C:\Users\DELL\AppData\Local\Programs\Python\Python313\Lib\site-packages\django\views\decorators\csrf.py", line 65, in _view_wrapper
    return view_func(request, *args, **kwargs)
  File "C:\Users\DELL\AppData\Local\Programs\Python\Python313\Lib\site-packages\django\views\generic\base.py", line 105, in view
    return self.dispatch(request, *args, **kwargs)
           ~~~~~~~~~~~~~^^^^^^^^^^^^^^^^^^^^^^^^^^
  File "C:\Users\DELL\AppData\Local\Programs\Python\Python313\Lib\site-packages\rest_framework\views.py", line 515, in dispatch
    response = self.handle_exception(exc)
  File "C:\Users\DELL\AppData\Local\Programs\Python\Python313\Lib\site-packages\rest_framework\views.py", line 475, in handle_exception
    self.raise_uncaught_exception(exc)
    ~~~~~~~~~~~~~~~~~~~~~~~~~~~~~^^^^^
  File "C:\Users\DELL\AppData\Local\Programs\Python\Python313\Lib\site-packages\rest_framework\views.py", line 486, in raise_uncaught_exception
    raise exc
  File "C:\Users\DELL\AppData\Local\Programs\Python\Python313\Lib\site-packages\rest_framework\views.py", line 512, in dispatch
    response = handler(request, *args, **kwargs)
  File "C:\Users\DELL\Desktop\projects\offline_voting_system\backend\accounts\views.py", line 56, in post
    if not voter.election.is_ongoing:
           ^^^^^
UnboundLocalError: cannot access local variable 'voter' where it is not associated with a value
ERROR 2025-08-29 14:22:11,383 log 11540 10220 Internal Server Error: /api/auth/voter_login/
Traceback (most recent call last):
  File "C:\Users\DELL\AppData\Local\Programs\Python\Python313\Lib\site-packages\django\core\handlers\exception.py", line 55, in inner
    response = get_response(request)
  File "C:\Users\DELL\AppData\Local\Programs\Python\Python313\Lib\site-packages\django\core\handlers\base.py", line 197, in _get_response
    response = wrapped_callback(request, *callback_args, **callback_kwargs)
  File "C:\Users\DELL\AppData\Local\Programs\Python\Python313\Lib\site-packages\django\views\decorators\csrf.py", line 65, in _view_wrapper
    return view_func(request, *args, **kwargs)
  File "C:\Users\DELL\AppData\Local\Programs\Python\Python313\Lib\site-packages\django\views\generic\base.py", line 105, in view
    return self.dispatch(request, *args, **kwargs)
           ~~~~~~~~~~~~~^^^^^^^^^^^^^^^^^^^^^^^^^^
  File "C:\Users\DELL\AppData\Local\Programs\Python\Python313\Lib\site-packages\rest_framework\views.py", line 515, in dispatch
    response = self.handle_exception(exc)
  File "C:\Users\DELL\AppData\Local\Programs\Python\Python313\Lib\site-packages\rest_framework\views.py", line 475, in handle_exception
    self.raise_uncaught_exception(exc)
    ~~~~~~~~~~~~~~~~~~~~~~~~~~~~~^^^^^
  File "C:\Users\DELL\AppData\Local\Programs\Python\Python313\Lib\site-packages\rest_framework\views.py", line 486, in raise_uncaught_exception
    raise exc
  File "C:\Users\DELL\AppData\Local\Programs\Python\Python313\Lib\site-packages\rest_framework\views.py", line 512, in dispatch
    response = handler(request, *args, **kwargs)
  File "C:\Users\DELL\Desktop\projects\offline_voting_system\backend\accounts\views.py", line 56, in post
    if not voter.election.is_ongoing:
           ^^^^^
UnboundLocalError: cannot access local variable 'voter' where it is not associated with a value
ERROR 2025-08-29 14:23:26,682 log 11540 10220 Internal Server Error: /api/auth/voter_login/
Traceback (most recent call last):
  File "C:\Users\DELL\AppData\Local\Programs\Python\Python313\Lib\site-packages\django\core\handlers\exception.py", line 55, in inner
    response = get_response(request)
  File "C:\Users\DELL\AppData\Local\Programs\Python\Python313\Lib\site-packages\django\core\handlers\base.py", line 197, in _get_response
    response = wrapped_callback(request, *callback_args, **callback_kwargs)
  File "C:\Users\DELL\AppData\Local\Programs\Python\Python313\Lib\site-packages\django\views\decorators\csrf.py", line 65, in _view_wrapper
    return view_func(request, *args, **kwargs)
  File "C:\Users\DELL\AppData\Local\Programs\Python\Python313\Lib\site-packages\django\views\generic\base.py", line 105, in view
    return self.dispatch(request, *args, **kwargs)
           ~~~~~~~~~~~~~^^^^^^^^^^^^^^^^^^^^^^^^^^
  File "C:\Users\DELL\AppData\Local\Programs\Python\Python313\Lib\site-packages\rest_framework\views.py", line 515, in dispatch
    response = self.handle_exception(exc)
  File "C:\Users\DELL\AppData\Local\Programs\Python\Python313\Lib\site-packages\rest_framework\views.py", line 475, in handle_exception
    self.raise_uncaught_exception(exc)
    ~~~~~~~~~~~~~~~~~~~~~~~~~~~~~^^^^^
  File "C:\Users\DELL\AppData\Local\Programs\Python\Python313\Lib\site-packages\rest_framework\views.py", line 486, in raise_uncaught_exception
    raise exc
  File "C:\Users\DELL\AppData\Local\Programs\Python\Python313\Lib\site-packages\rest_framework\views.py", line 512, in dispatch
    response = handler(request, *args, **kwargs)
  File "C:\Users\DELL\Desktop\projects\offline_voting_system\backend\accounts\views.py", line 56, in post
    if not voter.election.is_ongoing:
           ^^^^^
UnboundLocalError: cannot access local variable 'voter' where it is not associated with a value
ERROR 2025-08-29 14:23:58,404 log 11540 10220 Internal Server Error: /api/auth/voter_login/
Traceback (most recent call last):
  File "C:\Users\DELL\AppData\Local\Programs\Python\Python313\Lib\site-packages\django\core\handlers\exception.py", line 55, in inner
    response = get_response(request)
  File "C:\Users\DELL\AppData\Local\Programs\Python\Python313\Lib\site-packages\django\core\handlers\base.py", line 197, in _get_response
    response = wrapped_callback(request, *callback_args, **callback_kwargs)
  File "C:\Users\DELL\AppData\Local\Programs\Python\Python313\Lib\site-packages\django\views\decorators\csrf.py", line 65, in _view_wrapper
    return view_func(request, *args, **kwargs)
  File "C:\Users\DELL\AppData\Local\Programs\Python\Python313\Lib\site-packages\django\views\generic\base.py", line 105, in view
    return self.dispatch(request, *args, **kwargs)
           ~~~~~~~~~~~~~^^^^^^^^^^^^^^^^^^^^^^^^^^
  File "C:\Users\DELL\AppData\Local\Programs\Python\Python313\Lib\site-packages\rest_framework\views.py", line 515, in dispatch
    response = self.handle_exception(exc)
  File "C:\Users\DELL\AppData\Local\Programs\Python\Python313\Lib\site-packages\rest_framework\views.py", line 475, in handle_exception
    self.raise_uncaught_exception(exc)
    ~~~~~~~~~~~~~~~~~~~~~~~~~~~~~^^^^^
  File "C:\Users\DELL\AppData\Local\Programs\Python\Python313\Lib\site-packages\rest_framework\views.py", line 486, in raise_uncaught_exception
    raise exc
  File "C:\Users\DELL\AppData\Local\Programs\Python\Python313\Lib\site-packages\rest_framework\views.py", line 512, in dispatch
    response = handler(request, *args, **kwargs)
  File "C:\Users\DELL\Desktop\projects\offline_voting_system\backend\accounts\views.py", line 56, in post
    if not voter.election.is_ongoing:
           ^^^^^
UnboundLocalError: cannot access local variable 'voter' where it is not associated with a value
ERROR 2025-08-29 15:05:38,474 log 5328 5788 Internal Server Error: /api/auth/voter_login/
Traceback (most recent call last):
  File "C:\Users\DELL\AppData\Local\Programs\Python\Python313\Lib\site-packages\django\core\handlers\exception.py", line 55, in inner
    response = get_response(request)
  File "C:\Users\DELL\AppData\Local\Programs\Python\Python313\Lib\site-packages\django\core\handlers\base.py", line 197, in _get_response
    response = wrapped_callback(request, *callback_args, **callback_kwargs)
  File "C:\Users\DELL\AppData\Local\Programs\Python\Python313\Lib\site-packages\django\views\decorators\csrf.py", line 65, in _view_wrapper
    return view_func(request, *args, **kwargs)
  File "C:\Users\DELL\AppData\Local\Programs\Python\Python313\Lib\site-packages\django\views\generic\base.py", line 105, in view
    return self.dispatch(request, *args, **kwargs)
           ~~~~~~~~~~~~~^^^^^^^^^^^^^^^^^^^^^^^^^^
  File "C:\Users\DELL\AppData\Local\Programs\Python\Python313\Lib\site-packages\rest_framework\views.py", line 515, in dispatch
    response = self.handle_exception(exc)
  File "C:\Users\DELL\AppData\Local\Programs\Python\Python313\Lib\site-packages\rest_framework\views.py", line 475, in handle_exception
    self.raise_uncaught_exception(exc)
    ~~~~~~~~~~~~~~~~~~~~~~~~~~~~~^^^^^
  File "C:\Users\DELL\AppData\Local\Programs\Python\Python313\Lib\site-packages\rest_framework\views.py", line 486, in raise_uncaught_exception
    raise exc
  File "C:\Users\DELL\AppData\Local\Programs\Python\Python313\Lib\site-packages\rest_framework\views.py", line 512, in dispatch
    response = handler(request, *args, **kwargs)
  File "C:\Users\DELL\Desktop\projects\offline_voting_system\backend\accounts\views.py", line 56, in post
    if not voter.election.is_ongoing:
           ^^^^^
UnboundLocalError: cannot access local variable 'voter' where it is not associated with a value
ERROR 2025-08-29 15:06:18,089 log 5328 5788 Internal Server Error: /api/auth/voter_login/
Traceback (most recent call last):
  File "C:\Users\DELL\AppData\Local\Programs\Python\Python313\Lib\site-packages\django\core\handlers\exception.py", line 55, in inner
    response = get_response(request)
  File "C:\Users\DELL\AppData\Local\Programs\Python\Python313\Lib\site-packages\django\core\handlers\base.py", line 197, in _get_response
    response = wrapped_callback(request, *callback_args, **callback_kwargs)
  File "C:\Users\DELL\AppData\Local\Programs\Python\Python313\Lib\site-packages\django\views\decorators\csrf.py", line 65, in _view_wrapper
    return view_func(request, *args, **kwargs)
  File "C:\Users\DELL\AppData\Local\Programs\Python\Python313\Lib\site-packages\django\views\generic\base.py", line 105, in view
    return self.dispatch(request, *args, **kwargs)
           ~~~~~~~~~~~~~^^^^^^^^^^^^^^^^^^^^^^^^^^
  File "C:\Users\DELL\AppData\Local\Programs\Python\Python313\Lib\site-packages\rest_framework\views.py", line 515, in dispatch
    response = self.handle_exception(exc)
  File "C:\Users\DELL\AppData\Local\Programs\Python\Python313\Lib\site-packages\rest_framework\views.py", line 475, in handle_exception
    self.raise_uncaught_exception(exc)
    ~~~~~~~~~~~~~~~~~~~~~~~~~~~~~^^^^^
  File "C:\Users\DELL\AppData\Local\Programs\Python\Python313\Lib\site-packages\rest_framework\views.py", line 486, in raise_uncaught_exception
    raise exc
  File "C:\Users\DELL\AppData\Local\Programs\Python\Python313\Lib\site-packages\rest_framework\views.py", line 512, in dispatch
    response = handler(request, *args, **kwargs)
  File "C:\Users\DELL\Desktop\projects\offline_voting_system\backend\accounts\views.py", line 56, in post
    if not voter.election.is_ongoing:
           ^^^^^
UnboundLocalError: cannot access local variable 'voter' where it is not associated with a value
ERROR 2025-08-29 15:14:40,727 log 5328 8936 Internal Server Error: /api/auth/voter_login/
Traceback (most recent call last):
  File "C:\Users\DELL\AppData\Local\Programs\Python\Python313\Lib\site-packages\django\core\handlers\exception.py", line 55, in inner
    response = get_response(request)
  File "C:\Users\DELL\AppData\Local\Programs\Python\Python313\Lib\site-packages\django\core\handlers\base.py", line 197, in _get_response
    response = wrapped_callback(request, *callback_args, **callback_kwargs)
  File "C:\Users\DELL\AppData\Local\Programs\Python\Python313\Lib\site-packages\django\views\decorators\csrf.py", line 65, in _view_wrapper
    return view_func(request, *args, **kwargs)
  File "C:\Users\DELL\AppData\Local\Programs\Python\Python313\Lib\site-packages\django\views\generic\base.py", line 105, in view
    return self.dispatch(request, *args, **kwargs)
           ~~~~~~~~~~~~~^^^^^^^^^^^^^^^^^^^^^^^^^^
  File "C:\Users\DELL\AppData\Local\Programs\Python\Python313\Lib\site-packages\rest_framework\views.py", line 515, in dispatch
    response = self.handle_exception(exc)
  File "C:\Users\DELL\AppData\Local\Programs\Python\Python313\Lib\site-packages\rest_framework\views.py", line 475, in handle_exception
    self.raise_uncaught_exception(exc)
    ~~~~~~~~~~~~~~~~~~~~~~~~~~~~~^^^^^
  File "C:\Users\DELL\AppData\Local\Programs\Python\Python313\Lib\site-packages\rest_framework\views.py", line 486, in raise_uncaught_exception
    raise exc
  File "C:\Users\DELL\AppData\Local\Programs\Python\Python313\Lib\site-packages\rest_framework\views.py", line 512, in dispatch
    response = handler(request, *args, **kwargs)
  File "C:\Users\DELL\Desktop\projects\offline_voting_system\backend\accounts\views.py", line 56, in post
    if not voter.election.is_ongoing:
           ^^^^^
UnboundLocalError: cannot access local variable 'voter' where it is not associated with a value
ERROR 2025-08-29 15:16:44,688 log 10180 7928 Internal Server Error: /api/auth/voter_login/
Traceback (most recent call last):
  File "C:\Users\DELL\AppData\Local\Programs\Python\Python313\Lib\site-packages\django\core\handlers\exception.py", line 55, in inner
    response = get_response(request)
  File "C:\Users\DELL\AppData\Local\Programs\Python\Python313\Lib\site-packages\django\core\handlers\base.py", line 197, in _get_response
    response = wrapped_callback(request, *callback_args, **callback_kwargs)
  File "C:\Users\DELL\AppData\Local\Programs\Python\Python313\Lib\site-packages\django\views\decorators\csrf.py", line 65, in _view_wrapper
    return view_func(request, *args, **kwargs)
  File "C:\Users\DELL\AppData\Local\Programs\Python\Python313\Lib\site-packages\django\views\generic\base.py", line 105, in view
    return self.dispatch(request, *args, **kwargs)
           ~~~~~~~~~~~~~^^^^^^^^^^^^^^^^^^^^^^^^^^
  File "C:\Users\DELL\AppData\Local\Programs\Python\Python313\Lib\site-packages\rest_framework\views.py", line 515, in dispatch
    response = self.handle_exception(exc)
  File "C:\Users\DELL\AppData\Local\Programs\Python\Python313\Lib\site-packages\rest_framework\views.py", line 475, in handle_exception
    self.raise_uncaught_exception(exc)
    ~~~~~~~~~~~~~~~~~~~~~~~~~~~~~^^^^^
  File "C:\Users\DELL\AppData\Local\Programs\Python\Python313\Lib\site-packages\rest_framework\views.py", line 486, in raise_uncaught_exception
    raise exc
  File "C:\Users\DELL\AppData\Local\Programs\Python\Python313\Lib\site-packages\rest_framework\views.py", line 512, in dispatch
    response = handler(request, *args, **kwargs)
  File "C:\Users\DELL\Desktop\projects\offline_voting_system\backend\accounts\views.py", line 58, in post
    if not voter.election.is_ongoing:
           ^^^^^
UnboundLocalError: cannot access local variable 'voter' where it is not associated with a value
ERROR 2025-08-29 21:37:50,951 log 14208 6416 Internal Server Error: /api/elections
Traceback (most recent call last):
  File "C:\Users\DELL\AppData\Local\Programs\Python\Python313\Lib\site-packages\django\core\handlers\exception.py", line 55, in inner
    response = get_response(request)
  File "C:\Users\DELL\AppData\Local\Programs\Python\Python313\Lib\site-packages\django\utils\deprecation.py", line 122, in __call__
    response = self.process_response(request, response)
  File "C:\Users\DELL\AppData\Local\Programs\Python\Python313\Lib\site-packages\django\middleware\common.py", line 108, in process_response
    return self.response_redirect_class(self.get_full_path_with_slash(request))
                                        ~~~~~~~~~~~~~~~~~~~~~~~~~~~~~^^^^^^^^^
  File "C:\Users\DELL\AppData\Local\Programs\Python\Python313\Lib\site-packages\django\middleware\common.py", line 87, in get_full_path_with_slash
    raise RuntimeError(
    ...<9 lines>...
    )
RuntimeError: You called this URL via POST, but the URL doesn't end in a slash and you have APPEND_SLASH set. Django can't redirect to the slash URL while maintaining POST data. Change your form to point to localhost:8000/api/elections/ (note the trailing slash), or set APPEND_SLASH=False in your Django settings.
ERROR 2025-08-29 21:42:49,214 log 9192 14848 Internal Server Error: /api/elections/
Traceback (most recent call last):
  File "C:\Users\DELL\AppData\Local\Programs\Python\Python313\Lib\site-packages\django\core\handlers\exception.py", line 55, in inner
    response = get_response(request)
  File "C:\Users\DELL\AppData\Local\Programs\Python\Python313\Lib\site-packages\django\core\handlers\base.py", line 197, in _get_response
    response = wrapped_callback(request, *callback_args, **callback_kwargs)
  File "C:\Users\DELL\AppData\Local\Programs\Python\Python313\Lib\site-packages\django\views\decorators\csrf.py", line 65, in _view_wrapper
    return view_func(request, *args, **kwargs)
  File "C:\Users\DELL\AppData\Local\Programs\Python\Python313\Lib\site-packages\django\views\generic\base.py", line 105, in view
    return self.dispatch(request, *args, **kwargs)
           ~~~~~~~~~~~~~^^^^^^^^^^^^^^^^^^^^^^^^^^
  File "C:\Users\DELL\AppData\Local\Programs\Python\Python313\Lib\site-packages\rest_framework\views.py", line 515, in dispatch
    response = self.handle_exception(exc)
  File "C:\Users\DELL\AppData\Local\Programs\Python\Python313\Lib\site-packages\rest_framework\views.py", line 475, in handle_exception
    self.raise_uncaught_exception(exc)
    ~~~~~~~~~~~~~~~~~~~~~~~~~~~~~^^^^^
  File "C:\Users\DELL\AppData\Local\Programs\Python\Python313\Lib\site-packages\rest_framework\views.py", line 486, in raise_uncaught_exception
    raise exc
  File "C:\Users\DELL\AppData\Local\Programs\Python\Python313\Lib\site-packages\rest_framework\views.py", line 503, in dispatch
    self.initial(request, *args, **kwargs)
    ~~~~~~~~~~~~^^^^^^^^^^^^^^^^^^^^^^^^^^
  File "C:\Users\DELL\AppData\Local\Programs\Python\Python313\Lib\site-packages\rest_framework\views.py", line 420, in initial
    self.perform_authentication(request)
    ~~~~~~~~~~~~~~~~~~~~~~~~~~~^^^^^^^^^
  File "C:\Users\DELL\AppData\Local\Programs\Python\Python313\Lib\site-packages\rest_framework\views.py", line 330, in perform_authentication
    request.user
  File "C:\Users\DELL\AppData\Local\Programs\Python\Python313\Lib\site-packages\rest_framework\request.py", line 232, in user
    self._authenticate()
    ~~~~~~~~~~~~~~~~~~^^
  File "C:\Users\DELL\AppData\Local\Programs\Python\Python313\Lib\site-packages\rest_framework\request.py", line 385, in _authenticate
    user_auth_tuple = authenticator.authenticate(self)
  File "C:\Users\DELL\Desktop\projects\offline_voting_system\backend\accounts\auth.py", line 11, in authenticate
    print(token)
          ^^^^^
NameError: name 'token' is not defined. Did you mean: 'open'? Or did you forget to import 'token'?
ERROR 2025-08-29 21:43:05,492 log 9192 14848 Internal Server Error: /api/elections/
Traceback (most recent call last):
  File "C:\Users\DELL\AppData\Local\Programs\Python\Python313\Lib\site-packages\django\core\handlers\exception.py", line 55, in inner
    response = get_response(request)
  File "C:\Users\DELL\AppData\Local\Programs\Python\Python313\Lib\site-packages\django\core\handlers\base.py", line 197, in _get_response
    response = wrapped_callback(request, *callback_args, **callback_kwargs)
  File "C:\Users\DELL\AppData\Local\Programs\Python\Python313\Lib\site-packages\django\views\decorators\csrf.py", line 65, in _view_wrapper
    return view_func(request, *args, **kwargs)
  File "C:\Users\DELL\AppData\Local\Programs\Python\Python313\Lib\site-packages\django\views\generic\base.py", line 105, in view
    return self.dispatch(request, *args, **kwargs)
           ~~~~~~~~~~~~~^^^^^^^^^^^^^^^^^^^^^^^^^^
  File "C:\Users\DELL\AppData\Local\Programs\Python\Python313\Lib\site-packages\rest_framework\views.py", line 515, in dispatch
    response = self.handle_exception(exc)
  File "C:\Users\DELL\AppData\Local\Programs\Python\Python313\Lib\site-packages\rest_framework\views.py", line 475, in handle_exception
    self.raise_uncaught_exception(exc)
    ~~~~~~~~~~~~~~~~~~~~~~~~~~~~~^^^^^
  File "C:\Users\DELL\AppData\Local\Programs\Python\Python313\Lib\site-packages\rest_framework\views.py", line 486, in raise_uncaught_exception
    raise exc
  File "C:\Users\DELL\AppData\Local\Programs\Python\Python313\Lib\site-packages\rest_framework\views.py", line 503, in dispatch
    self.initial(request, *args, **kwargs)
    ~~~~~~~~~~~~^^^^^^^^^^^^^^^^^^^^^^^^^^
  File "C:\Users\DELL\AppData\Local\Programs\Python\Python313\Lib\site-packages\rest_framework\views.py", line 420, in initial
    self.perform_authentication(request)
    ~~~~~~~~~~~~~~~~~~~~~~~~~~~^^^^^^^^^
  File "C:\Users\DELL\AppData\Local\Programs\Python\Python313\Lib\site-packages\rest_framework\views.py", line 330, in perform_authentication
    request.user
  File "C:\Users\DELL\AppData\Local\Programs\Python\Python313\Lib\site-packages\rest_framework\request.py", line 232, in user
    self._authenticate()
    ~~~~~~~~~~~~~~~~~~^^
  File "C:\Users\DELL\AppData\Local\Programs\Python\Python313\Lib\site-packages\rest_framework\request.py", line 385, in _authenticate
    user_auth_tuple = authenticator.authenticate(self)
  File "C:\Users\DELL\Desktop\projects\offline_voting_system\backend\accounts\auth.py", line 11, in authenticate
    print(token)
          ^^^^^
NameError: name 'token' is not defined. Did you mean: 'open'? Or did you forget to import 'token'?
ERROR 2025-08-29 21:57:28,306 log 10436 13596 Internal Server Error: /api/elections/elections
Traceback (most recent call last):
  File "C:\Users\DELL\AppData\Local\Programs\Python\Python313\Lib\site-packages\django\core\handlers\exception.py", line 55, in inner
    response = get_response(request)
  File "C:\Users\DELL\AppData\Local\Programs\Python\Python313\Lib\site-packages\django\utils\deprecation.py", line 122, in __call__
    response = self.process_response(request, response)
  File "C:\Users\DELL\AppData\Local\Programs\Python\Python313\Lib\site-packages\django\middleware\common.py", line 108, in process_response
    return self.response_redirect_class(self.get_full_path_with_slash(request))
                                        ~~~~~~~~~~~~~~~~~~~~~~~~~~~~~^^^^^^^^^
  File "C:\Users\DELL\AppData\Local\Programs\Python\Python313\Lib\site-packages\django\middleware\common.py", line 87, in get_full_path_with_slash
    raise RuntimeError(
    ...<9 lines>...
    )
RuntimeError: You called this URL via POST, but the URL doesn't end in a slash and you have APPEND_SLASH set. Django can't redirect to the slash URL while maintaining POST data. Change your form to point to localhost:8000/api/elections/elections/ (note the trailing slash), or set APPEND_SLASH=False in your Django settings.
ERROR 2025-08-29 22:58:52,004 log 10436 11628 Internal Server Error: /api/elections/elections/
Traceback (most recent call last):
  File "C:\Users\DELL\AppData\Local\Programs\Python\Python313\Lib\site-packages\rest_framework\request.py", line 74, in wrap_attributeerrors
    yield
  File "C:\Users\DELL\AppData\Local\Programs\Python\Python313\Lib\site-packages\rest_framework\request.py", line 232, in user
    self._authenticate()
    ~~~~~~~~~~~~~~~~~~^^
  File "C:\Users\DELL\AppData\Local\Programs\Python\Python313\Lib\site-packages\rest_framework\request.py", line 385, in _authenticate
    user_auth_tuple = authenticator.authenticate(self)
  File "C:\Users\DELL\Desktop\projects\offline_voting_system\backend\accounts\auth.py", line 8, in authenticate
    token = auth_header.lower().split(' ')[1]
            ^^^^^^^^^^^^^^^^^
AttributeError: 'NoneType' object has no attribute 'lower'

During handling of the above exception, another exception occurred:

Traceback (most recent call last):
  File "C:\Users\DELL\AppData\Local\Programs\Python\Python313\Lib\site-packages\django\core\handlers\exception.py", line 55, in inner
    response = get_response(request)
  File "C:\Users\DELL\AppData\Local\Programs\Python\Python313\Lib\site-packages\django\core\handlers\base.py", line 197, in _get_response
    response = wrapped_callback(request, *callback_args, **callback_kwargs)
  File "C:\Users\DELL\AppData\Local\Programs\Python\Python313\Lib\site-packages\django\views\decorators\csrf.py", line 65, in _view_wrapper
    return view_func(request, *args, **kwargs)
  File "C:\Users\DELL\AppData\Local\Programs\Python\Python313\Lib\site-packages\rest_framework\viewsets.py", line 125, in view
    return self.dispatch(request, *args, **kwargs)
           ~~~~~~~~~~~~~^^^^^^^^^^^^^^^^^^^^^^^^^^
  File "C:\Users\DELL\AppData\Local\Programs\Python\Python313\Lib\site-packages\rest_framework\views.py", line 515, in dispatch
    response = self.handle_exception(exc)
  File "C:\Users\DELL\AppData\Local\Programs\Python\Python313\Lib\site-packages\rest_framework\views.py", line 475, in handle_exception
    self.raise_uncaught_exception(exc)
    ~~~~~~~~~~~~~~~~~~~~~~~~~~~~~^^^^^
  File "C:\Users\DELL\AppData\Local\Programs\Python\Python313\Lib\site-packages\rest_framework\views.py", line 486, in raise_uncaught_exception
    raise exc
  File "C:\Users\DELL\AppData\Local\Programs\Python\Python313\Lib\site-packages\rest_framework\views.py", line 503, in dispatch
    self.initial(request, *args, **kwargs)
    ~~~~~~~~~~~~^^^^^^^^^^^^^^^^^^^^^^^^^^
  File "C:\Users\DELL\AppData\Local\Programs\Python\Python313\Lib\site-packages\rest_framework\views.py", line 420, in initial
    self.perform_authentication(request)
    ~~~~~~~~~~~~~~~~~~~~~~~~~~~^^^^^^^^^
  File "C:\Users\DELL\AppData\Local\Programs\Python\Python313\Lib\site-packages\rest_framework\views.py", line 330, in perform_authentication
    request.user
  File "C:\Users\DELL\AppData\Local\Programs\Python\Python313\Lib\site-packages\rest_framework\request.py", line 231, in user
    with wrap_attributeerrors():
         ~~~~~~~~~~~~~~~~~~~~^^
  File "C:\Users\DELL\AppData\Local\Programs\Python\Python313\Lib\contextlib.py", line 162, in __exit__
    self.gen.throw(value)
    ~~~~~~~~~~~~~~^^^^^^^
  File "C:\Users\DELL\AppData\Local\Programs\Python\Python313\Lib\site-packages\rest_framework\request.py", line 78, in wrap_attributeerrors
    raise exc.with_traceback(info[2])
  File "C:\Users\DELL\AppData\Local\Programs\Python\Python313\Lib\site-packages\rest_framework\request.py", line 74, in wrap_attributeerrors
    yield
  File "C:\Users\DELL\AppData\Local\Programs\Python\Python313\Lib\site-packages\rest_framework\request.py", line 232, in user
    self._authenticate()
    ~~~~~~~~~~~~~~~~~~^^
  File "C:\Users\DELL\AppData\Local\Programs\Python\Python313\Lib\site-packages\rest_framework\request.py", line 385, in _authenticate
    user_auth_tuple = authenticator.authenticate(self)
  File "C:\Users\DELL\Desktop\projects\offline_voting_system\backend\accounts\auth.py", line 8, in authenticate
    token = auth_header.lower().split(' ')[1]
            ^^^^^^^^^^^^^^^^^
rest_framework.request.WrappedAttributeError: 'NoneType' object has no attribute 'lower'
ERROR 2025-08-29 22:58:52,404 log 10436 11944 Internal Server Error: /api/elections/elections/
Traceback (most recent call last):
  File "C:\Users\DELL\AppData\Local\Programs\Python\Python313\Lib\site-packages\rest_framework\request.py", line 74, in wrap_attributeerrors
    yield
  File "C:\Users\DELL\AppData\Local\Programs\Python\Python313\Lib\site-packages\rest_framework\request.py", line 232, in user
    self._authenticate()
    ~~~~~~~~~~~~~~~~~~^^
  File "C:\Users\DELL\AppData\Local\Programs\Python\Python313\Lib\site-packages\rest_framework\request.py", line 385, in _authenticate
    user_auth_tuple = authenticator.authenticate(self)
  File "C:\Users\DELL\Desktop\projects\offline_voting_system\backend\accounts\auth.py", line 8, in authenticate
    token = auth_header.lower().split(' ')[1]
            ^^^^^^^^^^^^^^^^^
AttributeError: 'NoneType' object has no attribute 'lower'

During handling of the above exception, another exception occurred:

Traceback (most recent call last):
  File "C:\Users\DELL\AppData\Local\Programs\Python\Python313\Lib\site-packages\django\core\handlers\exception.py", line 55, in inner
    response = get_response(request)
  File "C:\Users\DELL\AppData\Local\Programs\Python\Python313\Lib\site-packages\django\core\handlers\base.py", line 197, in _get_response
    response = wrapped_callback(request, *callback_args, **callback_kwargs)
  File "C:\Users\DELL\AppData\Local\Programs\Python\Python313\Lib\site-packages\django\views\decorators\csrf.py", line 65, in _view_wrapper
    return view_func(request, *args, **kwargs)
  File "C:\Users\DELL\AppData\Local\Programs\Python\Python313\Lib\site-packages\rest_framework\viewsets.py", line 125, in view
    return self.dispatch(request, *args, **kwargs)
           ~~~~~~~~~~~~~^^^^^^^^^^^^^^^^^^^^^^^^^^
  File "C:\Users\DELL\AppData\Local\Programs\Python\Python313\Lib\site-packages\rest_framework\views.py", line 515, in dispatch
    response = self.handle_exception(exc)
  File "C:\Users\DELL\AppData\Local\Programs\Python\Python313\Lib\site-packages\rest_framework\views.py", line 475, in handle_exception
    self.raise_uncaught_exception(exc)
    ~~~~~~~~~~~~~~~~~~~~~~~~~~~~~^^^^^
  File "C:\Users\DELL\AppData\Local\Programs\Python\Python313\Lib\site-packages\rest_framework\views.py", line 486, in raise_uncaught_exception
    raise exc
  File "C:\Users\DELL\AppData\Local\Programs\Python\Python313\Lib\site-packages\rest_framework\views.py", line 503, in dispatch
    self.initial(request, *args, **kwargs)
    ~~~~~~~~~~~~^^^^^^^^^^^^^^^^^^^^^^^^^^
  File "C:\Users\DELL\AppData\Local\Programs\Python\Python313\Lib\site-packages\rest_framework\views.py", line 420, in initial
    self.perform_authentication(request)
    ~~~~~~~~~~~~~~~~~~~~~~~~~~~^^^^^^^^^
  File "C:\Users\DELL\AppData\Local\Programs\Python\Python313\Lib\site-packages\rest_framework\views.py", line 330, in perform_authentication
    request.user
  File "C:\Users\DELL\AppData\Local\Programs\Python\Python313\Lib\site-packages\rest_framework\request.py", line 231, in user
    with wrap_attributeerrors():
         ~~~~~~~~~~~~~~~~~~~~^^
  File "C:\Users\DELL\AppData\Local\Programs\Python\Python313\Lib\contextlib.py", line 162, in __exit__
    self.gen.throw(value)
    ~~~~~~~~~~~~~~^^^^^^^
  File "C:\Users\DELL\AppData\Local\Programs\Python\Python313\Lib\site-packages\rest_framework\request.py", line 78, in wrap_attributeerrors
    raise exc.with_traceback(info[2])
  File "C:\Users\DELL\AppData\Local\Programs\Python\Python313\Lib\site-packages\rest_framework\request.py", line 74, in wrap_attributeerrors
    yield
  File "C:\Users\DELL\AppData\Local\Programs\Python\Python313\Lib\site-packages\rest_framework\request.py", line 232, in user
    self._authenticate()
    ~~~~~~~~~~~~~~~~~~^^
  File "C:\Users\DELL\AppData\Local\Programs\Python\Python313\Lib\site-packages\rest_framework\request.py", line 385, in _authenticate
    user_auth_tuple = authenticator.authenticate(self)
  File "C:\Users\DELL\Desktop\projects\offline_voting_system\backend\accounts\auth.py", line 8, in authenticate
    token = auth_header.lower().split(' ')[1]
            ^^^^^^^^^^^^^^^^^
rest_framework.request.WrappedAttributeError: 'NoneType' object has no attribute 'lower'
ERROR 2025-08-29 22:58:53,067 log 10436 404 Internal Server Error: /api/elections/elections/
Traceback (most recent call last):
  File "C:\Users\DELL\AppData\Local\Programs\Python\Python313\Lib\site-packages\rest_framework\request.py", line 74, in wrap_attributeerrors
    yield
  File "C:\Users\DELL\AppData\Local\Programs\Python\Python313\Lib\site-packages\rest_framework\request.py", line 232, in user
    self._authenticate()
    ~~~~~~~~~~~~~~~~~~^^
  File "C:\Users\DELL\AppData\Local\Programs\Python\Python313\Lib\site-packages\rest_framework\request.py", line 385, in _authenticate
    user_auth_tuple = authenticator.authenticate(self)
  File "C:\Users\DELL\Desktop\projects\offline_voting_system\backend\accounts\auth.py", line 8, in authenticate
    token = auth_header.lower().split(' ')[1]
            ^^^^^^^^^^^^^^^^^
AttributeError: 'NoneType' object has no attribute 'lower'

During handling of the above exception, another exception occurred:

Traceback (most recent call last):
  File "C:\Users\DELL\AppData\Local\Programs\Python\Python313\Lib\site-packages\django\core\handlers\exception.py", line 55, in inner
    response = get_response(request)
  File "C:\Users\DELL\AppData\Local\Programs\Python\Python313\Lib\site-packages\django\core\handlers\base.py", line 197, in _get_response
    response = wrapped_callback(request, *callback_args, **callback_kwargs)
  File "C:\Users\DELL\AppData\Local\Programs\Python\Python313\Lib\site-packages\django\views\decorators\csrf.py", line 65, in _view_wrapper
    return view_func(request, *args, **kwargs)
  File "C:\Users\DELL\AppData\Local\Programs\Python\Python313\Lib\site-packages\rest_framework\viewsets.py", line 125, in view
    return self.dispatch(request, *args, **kwargs)
           ~~~~~~~~~~~~~^^^^^^^^^^^^^^^^^^^^^^^^^^
  File "C:\Users\DELL\AppData\Local\Programs\Python\Python313\Lib\site-packages\rest_framework\views.py", line 515, in dispatch
    response = self.handle_exception(exc)
  File "C:\Users\DELL\AppData\Local\Programs\Python\Python313\Lib\site-packages\rest_framework\views.py", line 475, in handle_exception
    self.raise_uncaught_exception(exc)
    ~~~~~~~~~~~~~~~~~~~~~~~~~~~~~^^^^^
  File "C:\Users\DELL\AppData\Local\Programs\Python\Python313\Lib\site-packages\rest_framework\views.py", line 486, in raise_uncaught_exception
    raise exc
  File "C:\Users\DELL\AppData\Local\Programs\Python\Python313\Lib\site-packages\rest_framework\views.py", line 503, in dispatch
    self.initial(request, *args, **kwargs)
    ~~~~~~~~~~~~^^^^^^^^^^^^^^^^^^^^^^^^^^
  File "C:\Users\DELL\AppData\Local\Programs\Python\Python313\Lib\site-packages\rest_framework\views.py", line 420, in initial
    self.perform_authentication(request)
    ~~~~~~~~~~~~~~~~~~~~~~~~~~~^^^^^^^^^
  File "C:\Users\DELL\AppData\Local\Programs\Python\Python313\Lib\site-packages\rest_framework\views.py", line 330, in perform_authentication
    request.user
  File "C:\Users\DELL\AppData\Local\Programs\Python\Python313\Lib\site-packages\rest_framework\request.py", line 231, in user
    with wrap_attributeerrors():
         ~~~~~~~~~~~~~~~~~~~~^^
  File "C:\Users\DELL\AppData\Local\Programs\Python\Python313\Lib\contextlib.py", line 162, in __exit__
    self.gen.throw(value)
    ~~~~~~~~~~~~~~^^^^^^^
  File "C:\Users\DELL\AppData\Local\Programs\Python\Python313\Lib\site-packages\rest_framework\request.py", line 78, in wrap_attributeerrors
    raise exc.with_traceback(info[2])
  File "C:\Users\DELL\AppData\Local\Programs\Python\Python313\Lib\site-packages\rest_framework\request.py", line 74, in wrap_attributeerrors
    yield
  File "C:\Users\DELL\AppData\Local\Programs\Python\Python313\Lib\site-packages\rest_framework\request.py", line 232, in user
    self._authenticate()
    ~~~~~~~~~~~~~~~~~~^^
  File "C:\Users\DELL\AppData\Local\Programs\Python\Python313\Lib\site-packages\rest_framework\request.py", line 385, in _authenticate
    user_auth_tuple = authenticator.authenticate(self)
  File "C:\Users\DELL\Desktop\projects\offline_voting_system\backend\accounts\auth.py", line 8, in authenticate
    token = auth_header.lower().split(' ')[1]
            ^^^^^^^^^^^^^^^^^
rest_framework.request.WrappedAttributeError: 'NoneType' object has no attribute 'lower'
ERROR 2025-08-29 23:07:32,172 log 10436 3300 Internal Server Error: /api/elections/elections/
Traceback (most recent call last):
  File "C:\Users\DELL\AppData\Local\Programs\Python\Python313\Lib\site-packages\rest_framework\request.py", line 74, in wrap_attributeerrors
    yield
  File "C:\Users\DELL\AppData\Local\Programs\Python\Python313\Lib\site-packages\rest_framework\request.py", line 232, in user
    self._authenticate()
    ~~~~~~~~~~~~~~~~~~^^
  File "C:\Users\DELL\AppData\Local\Programs\Python\Python313\Lib\site-packages\rest_framework\request.py", line 385, in _authenticate
    user_auth_tuple = authenticator.authenticate(self)
  File "C:\Users\DELL\Desktop\projects\offline_voting_system\backend\accounts\auth.py", line 8, in authenticate
    token = auth_header.lower().split(' ')[1]
            ^^^^^^^^^^^^^^^^^
AttributeError: 'NoneType' object has no attribute 'lower'

During handling of the above exception, another exception occurred:

Traceback (most recent call last):
  File "C:\Users\DELL\AppData\Local\Programs\Python\Python313\Lib\site-packages\django\core\handlers\exception.py", line 55, in inner
    response = get_response(request)
  File "C:\Users\DELL\AppData\Local\Programs\Python\Python313\Lib\site-packages\django\core\handlers\base.py", line 197, in _get_response
    response = wrapped_callback(request, *callback_args, **callback_kwargs)
  File "C:\Users\DELL\AppData\Local\Programs\Python\Python313\Lib\site-packages\django\views\decorators\csrf.py", line 65, in _view_wrapper
    return view_func(request, *args, **kwargs)
  File "C:\Users\DELL\AppData\Local\Programs\Python\Python313\Lib\site-packages\rest_framework\viewsets.py", line 125, in view
    return self.dispatch(request, *args, **kwargs)
           ~~~~~~~~~~~~~^^^^^^^^^^^^^^^^^^^^^^^^^^
  File "C:\Users\DELL\AppData\Local\Programs\Python\Python313\Lib\site-packages\rest_framework\views.py", line 515, in dispatch
    response = self.handle_exception(exc)
  File "C:\Users\DELL\AppData\Local\Programs\Python\Python313\Lib\site-packages\rest_framework\views.py", line 475, in handle_exception
    self.raise_uncaught_exception(exc)
    ~~~~~~~~~~~~~~~~~~~~~~~~~~~~~^^^^^
  File "C:\Users\DELL\AppData\Local\Programs\Python\Python313\Lib\site-packages\rest_framework\views.py", line 486, in raise_uncaught_exception
    raise exc
  File "C:\Users\DELL\AppData\Local\Programs\Python\Python313\Lib\site-packages\rest_framework\views.py", line 503, in dispatch
    self.initial(request, *args, **kwargs)
    ~~~~~~~~~~~~^^^^^^^^^^^^^^^^^^^^^^^^^^
  File "C:\Users\DELL\AppData\Local\Programs\Python\Python313\Lib\site-packages\rest_framework\views.py", line 420, in initial
    self.perform_authentication(request)
    ~~~~~~~~~~~~~~~~~~~~~~~~~~~^^^^^^^^^
  File "C:\Users\DELL\AppData\Local\Programs\Python\Python313\Lib\site-packages\rest_framework\views.py", line 330, in perform_authentication
    request.user
  File "C:\Users\DELL\AppData\Local\Programs\Python\Python313\Lib\site-packages\rest_framework\request.py", line 231, in user
    with wrap_attributeerrors():
         ~~~~~~~~~~~~~~~~~~~~^^
  File "C:\Users\DELL\AppData\Local\Programs\Python\Python313\Lib\contextlib.py", line 162, in __exit__
    self.gen.throw(value)
    ~~~~~~~~~~~~~~^^^^^^^
  File "C:\Users\DELL\AppData\Local\Programs\Python\Python313\Lib\site-packages\rest_framework\request.py", line 78, in wrap_attributeerrors
    raise exc.with_traceback(info[2])
  File "C:\Users\DELL\AppData\Local\Programs\Python\Python313\Lib\site-packages\rest_framework\request.py", line 74, in wrap_attributeerrors
    yield
  File "C:\Users\DELL\AppData\Local\Programs\Python\Python313\Lib\site-packages\rest_framework\request.py", line 232, in user
    self._authenticate()
    ~~~~~~~~~~~~~~~~~~^^
  File "C:\Users\DELL\AppData\Local\Programs\Python\Python313\Lib\site-packages\rest_framework\request.py", line 385, in _authenticate
    user_auth_tuple = authenticator.authenticate(self)
  File "C:\Users\DELL\Desktop\projects\offline_voting_system\backend\accounts\auth.py", line 8, in authenticate
    token = auth_header.lower().split(' ')[1]
            ^^^^^^^^^^^^^^^^^
rest_framework.request.WrappedAttributeError: 'NoneType' object has no attribute 'lower'
ERROR 2025-08-29 23:07:32,349 log 10436 16028 Internal Server Error: /api/elections/elections/
Traceback (most recent call last):
  File "C:\Users\DELL\AppData\Local\Programs\Python\Python313\Lib\site-packages\rest_framework\request.py", line 74, in wrap_attributeerrors
    yield
  File "C:\Users\DELL\AppData\Local\Programs\Python\Python313\Lib\site-packages\rest_framework\request.py", line 232, in user
    self._authenticate()
    ~~~~~~~~~~~~~~~~~~^^
  File "C:\Users\DELL\AppData\Local\Programs\Python\Python313\Lib\site-packages\rest_framework\request.py", line 385, in _authenticate
    user_auth_tuple = authenticator.authenticate(self)
  File "C:\Users\DELL\Desktop\projects\offline_voting_system\backend\accounts\auth.py", line 8, in authenticate
    token = auth_header.lower().split(' ')[1]
            ^^^^^^^^^^^^^^^^^
AttributeError: 'NoneType' object has no attribute 'lower'

During handling of the above exception, another exception occurred:

Traceback (most recent call last):
  File "C:\Users\DELL\AppData\Local\Programs\Python\Python313\Lib\site-packages\django\core\handlers\exception.py", line 55, in inner
    response = get_response(request)
  File "C:\Users\DELL\AppData\Local\Programs\Python\Python313\Lib\site-packages\django\core\handlers\base.py", line 197, in _get_response
    response = wrapped_callback(request, *callback_args, **callback_kwargs)
  File "C:\Users\DELL\AppData\Local\Programs\Python\Python313\Lib\site-packages\django\views\decorators\csrf.py", line 65, in _view_wrapper
    return view_func(request, *args, **kwargs)
  File "C:\Users\DELL\AppData\Local\Programs\Python\Python313\Lib\site-packages\rest_framework\viewsets.py", line 125, in view
    return self.dispatch(request, *args, **kwargs)
           ~~~~~~~~~~~~~^^^^^^^^^^^^^^^^^^^^^^^^^^
  File "C:\Users\DELL\AppData\Local\Programs\Python\Python313\Lib\site-packages\rest_framework\views.py", line 515, in dispatch
    response = self.handle_exception(exc)
  File "C:\Users\DELL\AppData\Local\Programs\Python\Python313\Lib\site-packages\rest_framework\views.py", line 475, in handle_exception
    self.raise_uncaught_exception(exc)
    ~~~~~~~~~~~~~~~~~~~~~~~~~~~~~^^^^^
  File "C:\Users\DELL\AppData\Local\Programs\Python\Python313\Lib\site-packages\rest_framework\views.py", line 486, in raise_uncaught_exception
    raise exc
  File "C:\Users\DELL\AppData\Local\Programs\Python\Python313\Lib\site-packages\rest_framework\views.py", line 503, in dispatch
    self.initial(request, *args, **kwargs)
    ~~~~~~~~~~~~^^^^^^^^^^^^^^^^^^^^^^^^^^
  File "C:\Users\DELL\AppData\Local\Programs\Python\Python313\Lib\site-packages\rest_framework\views.py", line 420, in initial
    self.perform_authentication(request)
    ~~~~~~~~~~~~~~~~~~~~~~~~~~~^^^^^^^^^
  File "C:\Users\DELL\AppData\Local\Programs\Python\Python313\Lib\site-packages\rest_framework\views.py", line 330, in perform_authentication
    request.user
  File "C:\Users\DELL\AppData\Local\Programs\Python\Python313\Lib\site-packages\rest_framework\request.py", line 231, in user
    with wrap_attributeerrors():
         ~~~~~~~~~~~~~~~~~~~~^^
  File "C:\Users\DELL\AppData\Local\Programs\Python\Python313\Lib\contextlib.py", line 162, in __exit__
    self.gen.throw(value)
    ~~~~~~~~~~~~~~^^^^^^^
  File "C:\Users\DELL\AppData\Local\Programs\Python\Python313\Lib\site-packages\rest_framework\request.py", line 78, in wrap_attributeerrors
    raise exc.with_traceback(info[2])
  File "C:\Users\DELL\AppData\Local\Programs\Python\Python313\Lib\site-packages\rest_framework\request.py", line 74, in wrap_attributeerrors
    yield
  File "C:\Users\DELL\AppData\Local\Programs\Python\Python313\Lib\site-packages\rest_framework\request.py", line 232, in user
    self._authenticate()
    ~~~~~~~~~~~~~~~~~~^^
  File "C:\Users\DELL\AppData\Local\Programs\Python\Python313\Lib\site-packages\rest_framework\request.py", line 385, in _authenticate
    user_auth_tuple = authenticator.authenticate(self)
  File "C:\Users\DELL\Desktop\projects\offline_voting_system\backend\accounts\auth.py", line 8, in authenticate
    token = auth_header.lower().split(' ')[1]
            ^^^^^^^^^^^^^^^^^
rest_framework.request.WrappedAttributeError: 'NoneType' object has no attribute 'lower'
ERROR 2025-08-29 23:07:32,993 log 10436 17096 Internal Server Error: /api/elections/elections/
Traceback (most recent call last):
  File "C:\Users\DELL\AppData\Local\Programs\Python\Python313\Lib\site-packages\rest_framework\request.py", line 74, in wrap_attributeerrors
    yield
  File "C:\Users\DELL\AppData\Local\Programs\Python\Python313\Lib\site-packages\rest_framework\request.py", line 232, in user
    self._authenticate()
    ~~~~~~~~~~~~~~~~~~^^
  File "C:\Users\DELL\AppData\Local\Programs\Python\Python313\Lib\site-packages\rest_framework\request.py", line 385, in _authenticate
    user_auth_tuple = authenticator.authenticate(self)
  File "C:\Users\DELL\Desktop\projects\offline_voting_system\backend\accounts\auth.py", line 8, in authenticate
    token = auth_header.lower().split(' ')[1]
            ^^^^^^^^^^^^^^^^^
AttributeError: 'NoneType' object has no attribute 'lower'

During handling of the above exception, another exception occurred:

Traceback (most recent call last):
  File "C:\Users\DELL\AppData\Local\Programs\Python\Python313\Lib\site-packages\django\core\handlers\exception.py", line 55, in inner
    response = get_response(request)
  File "C:\Users\DELL\AppData\Local\Programs\Python\Python313\Lib\site-packages\django\core\handlers\base.py", line 197, in _get_response
    response = wrapped_callback(request, *callback_args, **callback_kwargs)
  File "C:\Users\DELL\AppData\Local\Programs\Python\Python313\Lib\site-packages\django\views\decorators\csrf.py", line 65, in _view_wrapper
    return view_func(request, *args, **kwargs)
  File "C:\Users\DELL\AppData\Local\Programs\Python\Python313\Lib\site-packages\rest_framework\viewsets.py", line 125, in view
    return self.dispatch(request, *args, **kwargs)
           ~~~~~~~~~~~~~^^^^^^^^^^^^^^^^^^^^^^^^^^
  File "C:\Users\DELL\AppData\Local\Programs\Python\Python313\Lib\site-packages\rest_framework\views.py", line 515, in dispatch
    response = self.handle_exception(exc)
  File "C:\Users\DELL\AppData\Local\Programs\Python\Python313\Lib\site-packages\rest_framework\views.py", line 475, in handle_exception
    self.raise_uncaught_exception(exc)
    ~~~~~~~~~~~~~~~~~~~~~~~~~~~~~^^^^^
  File "C:\Users\DELL\AppData\Local\Programs\Python\Python313\Lib\site-packages\rest_framework\views.py", line 486, in raise_uncaught_exception
    raise exc
  File "C:\Users\DELL\AppData\Local\Programs\Python\Python313\Lib\site-packages\rest_framework\views.py", line 503, in dispatch
    self.initial(request, *args, **kwargs)
    ~~~~~~~~~~~~^^^^^^^^^^^^^^^^^^^^^^^^^^
  File "C:\Users\DELL\AppData\Local\Programs\Python\Python313\Lib\site-packages\rest_framework\views.py", line 420, in initial
    self.perform_authentication(request)
    ~~~~~~~~~~~~~~~~~~~~~~~~~~~^^^^^^^^^
  File "C:\Users\DELL\AppData\Local\Programs\Python\Python313\Lib\site-packages\rest_framework\views.py", line 330, in perform_authentication
    request.user
  File "C:\Users\DELL\AppData\Local\Programs\Python\Python313\Lib\site-packages\rest_framework\request.py", line 231, in user
    with wrap_attributeerrors():
         ~~~~~~~~~~~~~~~~~~~~^^
  File "C:\Users\DELL\AppData\Local\Programs\Python\Python313\Lib\contextlib.py", line 162, in __exit__
    self.gen.throw(value)
    ~~~~~~~~~~~~~~^^^^^^^
  File "C:\Users\DELL\AppData\Local\Programs\Python\Python313\Lib\site-packages\rest_framework\request.py", line 78, in wrap_attributeerrors
    raise exc.with_traceback(info[2])
  File "C:\Users\DELL\AppData\Local\Programs\Python\Python313\Lib\site-packages\rest_framework\request.py", line 74, in wrap_attributeerrors
    yield
  File "C:\Users\DELL\AppData\Local\Programs\Python\Python313\Lib\site-packages\rest_framework\request.py", line 232, in user
    self._authenticate()
    ~~~~~~~~~~~~~~~~~~^^
  File "C:\Users\DELL\AppData\Local\Programs\Python\Python313\Lib\site-packages\rest_framework\request.py", line 385, in _authenticate
    user_auth_tuple = authenticator.authenticate(self)
  File "C:\Users\DELL\Desktop\projects\offline_voting_system\backend\accounts\auth.py", line 8, in authenticate
    token = auth_header.lower().split(' ')[1]
            ^^^^^^^^^^^^^^^^^
rest_framework.request.WrappedAttributeError: 'NoneType' object has no attribute 'lower'
ERROR 2025-08-29 23:08:31,541 log 10436 16912 Internal Server Error: /api/elections/elections/
Traceback (most recent call last):
  File "C:\Users\DELL\AppData\Local\Programs\Python\Python313\Lib\site-packages\rest_framework\request.py", line 74, in wrap_attributeerrors
    yield
  File "C:\Users\DELL\AppData\Local\Programs\Python\Python313\Lib\site-packages\rest_framework\request.py", line 232, in user
    self._authenticate()
    ~~~~~~~~~~~~~~~~~~^^
  File "C:\Users\DELL\AppData\Local\Programs\Python\Python313\Lib\site-packages\rest_framework\request.py", line 385, in _authenticate
    user_auth_tuple = authenticator.authenticate(self)
  File "C:\Users\DELL\Desktop\projects\offline_voting_system\backend\accounts\auth.py", line 8, in authenticate
    token = auth_header.lower().split(' ')[1]
            ^^^^^^^^^^^^^^^^^
AttributeError: 'NoneType' object has no attribute 'lower'

During handling of the above exception, another exception occurred:

Traceback (most recent call last):
  File "C:\Users\DELL\AppData\Local\Programs\Python\Python313\Lib\site-packages\django\core\handlers\exception.py", line 55, in inner
    response = get_response(request)
  File "C:\Users\DELL\AppData\Local\Programs\Python\Python313\Lib\site-packages\django\core\handlers\base.py", line 197, in _get_response
    response = wrapped_callback(request, *callback_args, **callback_kwargs)
  File "C:\Users\DELL\AppData\Local\Programs\Python\Python313\Lib\site-packages\django\views\decorators\csrf.py", line 65, in _view_wrapper
    return view_func(request, *args, **kwargs)
  File "C:\Users\DELL\AppData\Local\Programs\Python\Python313\Lib\site-packages\rest_framework\viewsets.py", line 125, in view
    return self.dispatch(request, *args, **kwargs)
           ~~~~~~~~~~~~~^^^^^^^^^^^^^^^^^^^^^^^^^^
  File "C:\Users\DELL\AppData\Local\Programs\Python\Python313\Lib\site-packages\rest_framework\views.py", line 515, in dispatch
    response = self.handle_exception(exc)
  File "C:\Users\DELL\AppData\Local\Programs\Python\Python313\Lib\site-packages\rest_framework\views.py", line 475, in handle_exception
    self.raise_uncaught_exception(exc)
    ~~~~~~~~~~~~~~~~~~~~~~~~~~~~~^^^^^
  File "C:\Users\DELL\AppData\Local\Programs\Python\Python313\Lib\site-packages\rest_framework\views.py", line 486, in raise_uncaught_exception
    raise exc
  File "C:\Users\DELL\AppData\Local\Programs\Python\Python313\Lib\site-packages\rest_framework\views.py", line 503, in dispatch
    self.initial(request, *args, **kwargs)
    ~~~~~~~~~~~~^^^^^^^^^^^^^^^^^^^^^^^^^^
  File "C:\Users\DELL\AppData\Local\Programs\Python\Python313\Lib\site-packages\rest_framework\views.py", line 420, in initial
    self.perform_authentication(request)
    ~~~~~~~~~~~~~~~~~~~~~~~~~~~^^^^^^^^^
  File "C:\Users\DELL\AppData\Local\Programs\Python\Python313\Lib\site-packages\rest_framework\views.py", line 330, in perform_authentication
    request.user
  File "C:\Users\DELL\AppData\Local\Programs\Python\Python313\Lib\site-packages\rest_framework\request.py", line 231, in user
    with wrap_attributeerrors():
         ~~~~~~~~~~~~~~~~~~~~^^
  File "C:\Users\DELL\AppData\Local\Programs\Python\Python313\Lib\contextlib.py", line 162, in __exit__
    self.gen.throw(value)
    ~~~~~~~~~~~~~~^^^^^^^
  File "C:\Users\DELL\AppData\Local\Programs\Python\Python313\Lib\site-packages\rest_framework\request.py", line 78, in wrap_attributeerrors
    raise exc.with_traceback(info[2])
  File "C:\Users\DELL\AppData\Local\Programs\Python\Python313\Lib\site-packages\rest_framework\request.py", line 74, in wrap_attributeerrors
    yield
  File "C:\Users\DELL\AppData\Local\Programs\Python\Python313\Lib\site-packages\rest_framework\request.py", line 232, in user
    self._authenticate()
    ~~~~~~~~~~~~~~~~~~^^
  File "C:\Users\DELL\AppData\Local\Programs\Python\Python313\Lib\site-packages\rest_framework\request.py", line 385, in _authenticate
    user_auth_tuple = authenticator.authenticate(self)
  File "C:\Users\DELL\Desktop\projects\offline_voting_system\backend\accounts\auth.py", line 8, in authenticate
    token = auth_header.lower().split(' ')[1]
            ^^^^^^^^^^^^^^^^^
rest_framework.request.WrappedAttributeError: 'NoneType' object has no attribute 'lower'
ERROR 2025-08-29 23:10:28,389 log 10436 12568 Internal Server Error: /api/elections/elections/
Traceback (most recent call last):
  File "C:\Users\DELL\AppData\Local\Programs\Python\Python313\Lib\site-packages\rest_framework\request.py", line 74, in wrap_attributeerrors
    yield
  File "C:\Users\DELL\AppData\Local\Programs\Python\Python313\Lib\site-packages\rest_framework\request.py", line 232, in user
    self._authenticate()
    ~~~~~~~~~~~~~~~~~~^^
  File "C:\Users\DELL\AppData\Local\Programs\Python\Python313\Lib\site-packages\rest_framework\request.py", line 385, in _authenticate
    user_auth_tuple = authenticator.authenticate(self)
  File "C:\Users\DELL\Desktop\projects\offline_voting_system\backend\accounts\auth.py", line 8, in authenticate
    token = auth_header.lower().split(' ')[1]
            ^^^^^^^^^^^^^^^^^
AttributeError: 'NoneType' object has no attribute 'lower'

During handling of the above exception, another exception occurred:

Traceback (most recent call last):
  File "C:\Users\DELL\AppData\Local\Programs\Python\Python313\Lib\site-packages\django\core\handlers\exception.py", line 55, in inner
    response = get_response(request)
  File "C:\Users\DELL\AppData\Local\Programs\Python\Python313\Lib\site-packages\django\core\handlers\base.py", line 197, in _get_response
    response = wrapped_callback(request, *callback_args, **callback_kwargs)
  File "C:\Users\DELL\AppData\Local\Programs\Python\Python313\Lib\site-packages\django\views\decorators\csrf.py", line 65, in _view_wrapper
    return view_func(request, *args, **kwargs)
  File "C:\Users\DELL\AppData\Local\Programs\Python\Python313\Lib\site-packages\rest_framework\viewsets.py", line 125, in view
    return self.dispatch(request, *args, **kwargs)
           ~~~~~~~~~~~~~^^^^^^^^^^^^^^^^^^^^^^^^^^
  File "C:\Users\DELL\AppData\Local\Programs\Python\Python313\Lib\site-packages\rest_framework\views.py", line 515, in dispatch
    response = self.handle_exception(exc)
  File "C:\Users\DELL\AppData\Local\Programs\Python\Python313\Lib\site-packages\rest_framework\views.py", line 475, in handle_exception
    self.raise_uncaught_exception(exc)
    ~~~~~~~~~~~~~~~~~~~~~~~~~~~~~^^^^^
  File "C:\Users\DELL\AppData\Local\Programs\Python\Python313\Lib\site-packages\rest_framework\views.py", line 486, in raise_uncaught_exception
    raise exc
  File "C:\Users\DELL\AppData\Local\Programs\Python\Python313\Lib\site-packages\rest_framework\views.py", line 503, in dispatch
    self.initial(request, *args, **kwargs)
    ~~~~~~~~~~~~^^^^^^^^^^^^^^^^^^^^^^^^^^
  File "C:\Users\DELL\AppData\Local\Programs\Python\Python313\Lib\site-packages\rest_framework\views.py", line 420, in initial
    self.perform_authentication(request)
    ~~~~~~~~~~~~~~~~~~~~~~~~~~~^^^^^^^^^
  File "C:\Users\DELL\AppData\Local\Programs\Python\Python313\Lib\site-packages\rest_framework\views.py", line 330, in perform_authentication
    request.user
  File "C:\Users\DELL\AppData\Local\Programs\Python\Python313\Lib\site-packages\rest_framework\request.py", line 231, in user
    with wrap_attributeerrors():
         ~~~~~~~~~~~~~~~~~~~~^^
  File "C:\Users\DELL\AppData\Local\Programs\Python\Python313\Lib\contextlib.py", line 162, in __exit__
    self.gen.throw(value)
    ~~~~~~~~~~~~~~^^^^^^^
  File "C:\Users\DELL\AppData\Local\Programs\Python\Python313\Lib\site-packages\rest_framework\request.py", line 78, in wrap_attributeerrors
    raise exc.with_traceback(info[2])
  File "C:\Users\DELL\AppData\Local\Programs\Python\Python313\Lib\site-packages\rest_framework\request.py", line 74, in wrap_attributeerrors
    yield
  File "C:\Users\DELL\AppData\Local\Programs\Python\Python313\Lib\site-packages\rest_framework\request.py", line 232, in user
    self._authenticate()
    ~~~~~~~~~~~~~~~~~~^^
  File "C:\Users\DELL\AppData\Local\Programs\Python\Python313\Lib\site-packages\rest_framework\request.py", line 385, in _authenticate
    user_auth_tuple = authenticator.authenticate(self)
  File "C:\Users\DELL\Desktop\projects\offline_voting_system\backend\accounts\auth.py", line 8, in authenticate
    token = auth_header.lower().split(' ')[1]
            ^^^^^^^^^^^^^^^^^
rest_framework.request.WrappedAttributeError: 'NoneType' object has no attribute 'lower'
ERROR 2025-08-29 23:10:28,714 log 10436 17192 Internal Server Error: /api/elections/elections/
Traceback (most recent call last):
  File "C:\Users\DELL\AppData\Local\Programs\Python\Python313\Lib\site-packages\rest_framework\request.py", line 74, in wrap_attributeerrors
    yield
  File "C:\Users\DELL\AppData\Local\Programs\Python\Python313\Lib\site-packages\rest_framework\request.py", line 232, in user
    self._authenticate()
    ~~~~~~~~~~~~~~~~~~^^
  File "C:\Users\DELL\AppData\Local\Programs\Python\Python313\Lib\site-packages\rest_framework\request.py", line 385, in _authenticate
    user_auth_tuple = authenticator.authenticate(self)
  File "C:\Users\DELL\Desktop\projects\offline_voting_system\backend\accounts\auth.py", line 8, in authenticate
    token = auth_header.lower().split(' ')[1]
            ^^^^^^^^^^^^^^^^^
AttributeError: 'NoneType' object has no attribute 'lower'

During handling of the above exception, another exception occurred:

Traceback (most recent call last):
  File "C:\Users\DELL\AppData\Local\Programs\Python\Python313\Lib\site-packages\django\core\handlers\exception.py", line 55, in inner
    response = get_response(request)
  File "C:\Users\DELL\AppData\Local\Programs\Python\Python313\Lib\site-packages\django\core\handlers\base.py", line 197, in _get_response
    response = wrapped_callback(request, *callback_args, **callback_kwargs)
  File "C:\Users\DELL\AppData\Local\Programs\Python\Python313\Lib\site-packages\django\views\decorators\csrf.py", line 65, in _view_wrapper
    return view_func(request, *args, **kwargs)
  File "C:\Users\DELL\AppData\Local\Programs\Python\Python313\Lib\site-packages\rest_framework\viewsets.py", line 125, in view
    return self.dispatch(request, *args, **kwargs)
           ~~~~~~~~~~~~~^^^^^^^^^^^^^^^^^^^^^^^^^^
  File "C:\Users\DELL\AppData\Local\Programs\Python\Python313\Lib\site-packages\rest_framework\views.py", line 515, in dispatch
    response = self.handle_exception(exc)
  File "C:\Users\DELL\AppData\Local\Programs\Python\Python313\Lib\site-packages\rest_framework\views.py", line 475, in handle_exception
    self.raise_uncaught_exception(exc)
    ~~~~~~~~~~~~~~~~~~~~~~~~~~~~~^^^^^
  File "C:\Users\DELL\AppData\Local\Programs\Python\Python313\Lib\site-packages\rest_framework\views.py", line 486, in raise_uncaught_exception
    raise exc
  File "C:\Users\DELL\AppData\Local\Programs\Python\Python313\Lib\site-packages\rest_framework\views.py", line 503, in dispatch
    self.initial(request, *args, **kwargs)
    ~~~~~~~~~~~~^^^^^^^^^^^^^^^^^^^^^^^^^^
  File "C:\Users\DELL\AppData\Local\Programs\Python\Python313\Lib\site-packages\rest_framework\views.py", line 420, in initial
    self.perform_authentication(request)
    ~~~~~~~~~~~~~~~~~~~~~~~~~~~^^^^^^^^^
  File "C:\Users\DELL\AppData\Local\Programs\Python\Python313\Lib\site-packages\rest_framework\views.py", line 330, in perform_authentication
    request.user
  File "C:\Users\DELL\AppData\Local\Programs\Python\Python313\Lib\site-packages\rest_framework\request.py", line 231, in user
    with wrap_attributeerrors():
         ~~~~~~~~~~~~~~~~~~~~^^
  File "C:\Users\DELL\AppData\Local\Programs\Python\Python313\Lib\contextlib.py", line 162, in __exit__
    self.gen.throw(value)
    ~~~~~~~~~~~~~~^^^^^^^
  File "C:\Users\DELL\AppData\Local\Programs\Python\Python313\Lib\site-packages\rest_framework\request.py", line 78, in wrap_attributeerrors
    raise exc.with_traceback(info[2])
  File "C:\Users\DELL\AppData\Local\Programs\Python\Python313\Lib\site-packages\rest_framework\request.py", line 74, in wrap_attributeerrors
    yield
  File "C:\Users\DELL\AppData\Local\Programs\Python\Python313\Lib\site-packages\rest_framework\request.py", line 232, in user
    self._authenticate()
    ~~~~~~~~~~~~~~~~~~^^
  File "C:\Users\DELL\AppData\Local\Programs\Python\Python313\Lib\site-packages\rest_framework\request.py", line 385, in _authenticate
    user_auth_tuple = authenticator.authenticate(self)
  File "C:\Users\DELL\Desktop\projects\offline_voting_system\backend\accounts\auth.py", line 8, in authenticate
    token = auth_header.lower().split(' ')[1]
            ^^^^^^^^^^^^^^^^^
rest_framework.request.WrappedAttributeError: 'NoneType' object has no attribute 'lower'
ERROR 2025-08-29 23:29:42,760 log 10436 14400 Internal Server Error: /api/elections/elections/
Traceback (most recent call last):
  File "C:\Users\DELL\AppData\Local\Programs\Python\Python313\Lib\site-packages\rest_framework\request.py", line 74, in wrap_attributeerrors
    yield
  File "C:\Users\DELL\AppData\Local\Programs\Python\Python313\Lib\site-packages\rest_framework\request.py", line 232, in user
    self._authenticate()
    ~~~~~~~~~~~~~~~~~~^^
  File "C:\Users\DELL\AppData\Local\Programs\Python\Python313\Lib\site-packages\rest_framework\request.py", line 385, in _authenticate
    user_auth_tuple = authenticator.authenticate(self)
  File "C:\Users\DELL\Desktop\projects\offline_voting_system\backend\accounts\auth.py", line 8, in authenticate
    token = auth_header.lower().split(' ')[1]
            ^^^^^^^^^^^^^^^^^
AttributeError: 'NoneType' object has no attribute 'lower'

During handling of the above exception, another exception occurred:

Traceback (most recent call last):
  File "C:\Users\DELL\AppData\Local\Programs\Python\Python313\Lib\site-packages\django\core\handlers\exception.py", line 55, in inner
    response = get_response(request)
  File "C:\Users\DELL\AppData\Local\Programs\Python\Python313\Lib\site-packages\django\core\handlers\base.py", line 197, in _get_response
    response = wrapped_callback(request, *callback_args, **callback_kwargs)
  File "C:\Users\DELL\AppData\Local\Programs\Python\Python313\Lib\site-packages\django\views\decorators\csrf.py", line 65, in _view_wrapper
    return view_func(request, *args, **kwargs)
  File "C:\Users\DELL\AppData\Local\Programs\Python\Python313\Lib\site-packages\rest_framework\viewsets.py", line 125, in view
    return self.dispatch(request, *args, **kwargs)
           ~~~~~~~~~~~~~^^^^^^^^^^^^^^^^^^^^^^^^^^
  File "C:\Users\DELL\AppData\Local\Programs\Python\Python313\Lib\site-packages\rest_framework\views.py", line 515, in dispatch
    response = self.handle_exception(exc)
  File "C:\Users\DELL\AppData\Local\Programs\Python\Python313\Lib\site-packages\rest_framework\views.py", line 475, in handle_exception
    self.raise_uncaught_exception(exc)
    ~~~~~~~~~~~~~~~~~~~~~~~~~~~~~^^^^^
  File "C:\Users\DELL\AppData\Local\Programs\Python\Python313\Lib\site-packages\rest_framework\views.py", line 486, in raise_uncaught_exception
    raise exc
  File "C:\Users\DELL\AppData\Local\Programs\Python\Python313\Lib\site-packages\rest_framework\views.py", line 503, in dispatch
    self.initial(request, *args, **kwargs)
    ~~~~~~~~~~~~^^^^^^^^^^^^^^^^^^^^^^^^^^
  File "C:\Users\DELL\AppData\Local\Programs\Python\Python313\Lib\site-packages\rest_framework\views.py", line 420, in initial
    self.perform_authentication(request)
    ~~~~~~~~~~~~~~~~~~~~~~~~~~~^^^^^^^^^
  File "C:\Users\DELL\AppData\Local\Programs\Python\Python313\Lib\site-packages\rest_framework\views.py", line 330, in perform_authentication
    request.user
  File "C:\Users\DELL\AppData\Local\Programs\Python\Python313\Lib\site-packages\rest_framework\request.py", line 231, in user
    with wrap_attributeerrors():
         ~~~~~~~~~~~~~~~~~~~~^^
  File "C:\Users\DELL\AppData\Local\Programs\Python\Python313\Lib\contextlib.py", line 162, in __exit__
    self.gen.throw(value)
    ~~~~~~~~~~~~~~^^^^^^^
  File "C:\Users\DELL\AppData\Local\Programs\Python\Python313\Lib\site-packages\rest_framework\request.py", line 78, in wrap_attributeerrors
    raise exc.with_traceback(info[2])
  File "C:\Users\DELL\AppData\Local\Programs\Python\Python313\Lib\site-packages\rest_framework\request.py", line 74, in wrap_attributeerrors
    yield
  File "C:\Users\DELL\AppData\Local\Programs\Python\Python313\Lib\site-packages\rest_framework\request.py", line 232, in user
    self._authenticate()
    ~~~~~~~~~~~~~~~~~~^^
  File "C:\Users\DELL\AppData\Local\Programs\Python\Python313\Lib\site-packages\rest_framework\request.py", line 385, in _authenticate
    user_auth_tuple = authenticator.authenticate(self)
  File "C:\Users\DELL\Desktop\projects\offline_voting_system\backend\accounts\auth.py", line 8, in authenticate
    token = auth_header.lower().split(' ')[1]
            ^^^^^^^^^^^^^^^^^
rest_framework.request.WrappedAttributeError: 'NoneType' object has no attribute 'lower'
ERROR 2025-08-29 23:32:16,565 log 10436 6620 Internal Server Error: /api/elections/elections/
Traceback (most recent call last):
  File "C:\Users\DELL\AppData\Local\Programs\Python\Python313\Lib\site-packages\rest_framework\request.py", line 74, in wrap_attributeerrors
    yield
  File "C:\Users\DELL\AppData\Local\Programs\Python\Python313\Lib\site-packages\rest_framework\request.py", line 232, in user
    self._authenticate()
    ~~~~~~~~~~~~~~~~~~^^
  File "C:\Users\DELL\AppData\Local\Programs\Python\Python313\Lib\site-packages\rest_framework\request.py", line 385, in _authenticate
    user_auth_tuple = authenticator.authenticate(self)
  File "C:\Users\DELL\Desktop\projects\offline_voting_system\backend\accounts\auth.py", line 8, in authenticate
    token = auth_header.lower().split(' ')[1]
            ^^^^^^^^^^^^^^^^^
AttributeError: 'NoneType' object has no attribute 'lower'

During handling of the above exception, another exception occurred:

Traceback (most recent call last):
  File "C:\Users\DELL\AppData\Local\Programs\Python\Python313\Lib\site-packages\django\core\handlers\exception.py", line 55, in inner
    response = get_response(request)
  File "C:\Users\DELL\AppData\Local\Programs\Python\Python313\Lib\site-packages\django\core\handlers\base.py", line 197, in _get_response
    response = wrapped_callback(request, *callback_args, **callback_kwargs)
  File "C:\Users\DELL\AppData\Local\Programs\Python\Python313\Lib\site-packages\django\views\decorators\csrf.py", line 65, in _view_wrapper
    return view_func(request, *args, **kwargs)
  File "C:\Users\DELL\AppData\Local\Programs\Python\Python313\Lib\site-packages\rest_framework\viewsets.py", line 125, in view
    return self.dispatch(request, *args, **kwargs)
           ~~~~~~~~~~~~~^^^^^^^^^^^^^^^^^^^^^^^^^^
  File "C:\Users\DELL\AppData\Local\Programs\Python\Python313\Lib\site-packages\rest_framework\views.py", line 515, in dispatch
    response = self.handle_exception(exc)
  File "C:\Users\DELL\AppData\Local\Programs\Python\Python313\Lib\site-packages\rest_framework\views.py", line 475, in handle_exception
    self.raise_uncaught_exception(exc)
    ~~~~~~~~~~~~~~~~~~~~~~~~~~~~~^^^^^
  File "C:\Users\DELL\AppData\Local\Programs\Python\Python313\Lib\site-packages\rest_framework\views.py", line 486, in raise_uncaught_exception
    raise exc
  File "C:\Users\DELL\AppData\Local\Programs\Python\Python313\Lib\site-packages\rest_framework\views.py", line 503, in dispatch
    self.initial(request, *args, **kwargs)
    ~~~~~~~~~~~~^^^^^^^^^^^^^^^^^^^^^^^^^^
  File "C:\Users\DELL\AppData\Local\Programs\Python\Python313\Lib\site-packages\rest_framework\views.py", line 420, in initial
    self.perform_authentication(request)
    ~~~~~~~~~~~~~~~~~~~~~~~~~~~^^^^^^^^^
  File "C:\Users\DELL\AppData\Local\Programs\Python\Python313\Lib\site-packages\rest_framework\views.py", line 330, in perform_authentication
    request.user
  File "C:\Users\DELL\AppData\Local\Programs\Python\Python313\Lib\site-packages\rest_framework\request.py", line 231, in user
    with wrap_attributeerrors():
         ~~~~~~~~~~~~~~~~~~~~^^
  File "C:\Users\DELL\AppData\Local\Programs\Python\Python313\Lib\contextlib.py", line 162, in __exit__
    self.gen.throw(value)
    ~~~~~~~~~~~~~~^^^^^^^
  File "C:\Users\DELL\AppData\Local\Programs\Python\Python313\Lib\site-packages\rest_framework\request.py", line 78, in wrap_attributeerrors
    raise exc.with_traceback(info[2])
  File "C:\Users\DELL\AppData\Local\Programs\Python\Python313\Lib\site-packages\rest_framework\request.py", line 74, in wrap_attributeerrors
    yield
  File "C:\Users\DELL\AppData\Local\Programs\Python\Python313\Lib\site-packages\rest_framework\request.py", line 232, in user
    self._authenticate()
    ~~~~~~~~~~~~~~~~~~^^
  File "C:\Users\DELL\AppData\Local\Programs\Python\Python313\Lib\site-packages\rest_framework\request.py", line 385, in _authenticate
    user_auth_tuple = authenticator.authenticate(self)
  File "C:\Users\DELL\Desktop\projects\offline_voting_system\backend\accounts\auth.py", line 8, in authenticate
    token = auth_header.lower().split(' ')[1]
            ^^^^^^^^^^^^^^^^^
rest_framework.request.WrappedAttributeError: 'NoneType' object has no attribute 'lower'
ERROR 2025-08-29 23:32:30,107 log 10436 8724 Internal Server Error: /api/elections/elections/
Traceback (most recent call last):
  File "C:\Users\DELL\AppData\Local\Programs\Python\Python313\Lib\site-packages\rest_framework\request.py", line 74, in wrap_attributeerrors
    yield
  File "C:\Users\DELL\AppData\Local\Programs\Python\Python313\Lib\site-packages\rest_framework\request.py", line 232, in user
    self._authenticate()
    ~~~~~~~~~~~~~~~~~~^^
  File "C:\Users\DELL\AppData\Local\Programs\Python\Python313\Lib\site-packages\rest_framework\request.py", line 385, in _authenticate
    user_auth_tuple = authenticator.authenticate(self)
  File "C:\Users\DELL\Desktop\projects\offline_voting_system\backend\accounts\auth.py", line 8, in authenticate
    token = auth_header.lower().split(' ')[1]
            ^^^^^^^^^^^^^^^^^
AttributeError: 'NoneType' object has no attribute 'lower'

During handling of the above exception, another exception occurred:

Traceback (most recent call last):
  File "C:\Users\DELL\AppData\Local\Programs\Python\Python313\Lib\site-packages\django\core\handlers\exception.py", line 55, in inner
    response = get_response(request)
  File "C:\Users\DELL\AppData\Local\Programs\Python\Python313\Lib\site-packages\django\core\handlers\base.py", line 197, in _get_response
    response = wrapped_callback(request, *callback_args, **callback_kwargs)
  File "C:\Users\DELL\AppData\Local\Programs\Python\Python313\Lib\site-packages\django\views\decorators\csrf.py", line 65, in _view_wrapper
    return view_func(request, *args, **kwargs)
  File "C:\Users\DELL\AppData\Local\Programs\Python\Python313\Lib\site-packages\rest_framework\viewsets.py", line 125, in view
    return self.dispatch(request, *args, **kwargs)
           ~~~~~~~~~~~~~^^^^^^^^^^^^^^^^^^^^^^^^^^
  File "C:\Users\DELL\AppData\Local\Programs\Python\Python313\Lib\site-packages\rest_framework\views.py", line 515, in dispatch
    response = self.handle_exception(exc)
  File "C:\Users\DELL\AppData\Local\Programs\Python\Python313\Lib\site-packages\rest_framework\views.py", line 475, in handle_exception
    self.raise_uncaught_exception(exc)
    ~~~~~~~~~~~~~~~~~~~~~~~~~~~~~^^^^^
  File "C:\Users\DELL\AppData\Local\Programs\Python\Python313\Lib\site-packages\rest_framework\views.py", line 486, in raise_uncaught_exception
    raise exc
  File "C:\Users\DELL\AppData\Local\Programs\Python\Python313\Lib\site-packages\rest_framework\views.py", line 503, in dispatch
    self.initial(request, *args, **kwargs)
    ~~~~~~~~~~~~^^^^^^^^^^^^^^^^^^^^^^^^^^
  File "C:\Users\DELL\AppData\Local\Programs\Python\Python313\Lib\site-packages\rest_framework\views.py", line 420, in initial
    self.perform_authentication(request)
    ~~~~~~~~~~~~~~~~~~~~~~~~~~~^^^^^^^^^
  File "C:\Users\DELL\AppData\Local\Programs\Python\Python313\Lib\site-packages\rest_framework\views.py", line 330, in perform_authentication
    request.user
  File "C:\Users\DELL\AppData\Local\Programs\Python\Python313\Lib\site-packages\rest_framework\request.py", line 231, in user
    with wrap_attributeerrors():
         ~~~~~~~~~~~~~~~~~~~~^^
  File "C:\Users\DELL\AppData\Local\Programs\Python\Python313\Lib\contextlib.py", line 162, in __exit__
    self.gen.throw(value)
    ~~~~~~~~~~~~~~^^^^^^^
  File "C:\Users\DELL\AppData\Local\Programs\Python\Python313\Lib\site-packages\rest_framework\request.py", line 78, in wrap_attributeerrors
    raise exc.with_traceback(info[2])
  File "C:\Users\DELL\AppData\Local\Programs\Python\Python313\Lib\site-packages\rest_framework\request.py", line 74, in wrap_attributeerrors
    yield
  File "C:\Users\DELL\AppData\Local\Programs\Python\Python313\Lib\site-packages\rest_framework\request.py", line 232, in user
    self._authenticate()
    ~~~~~~~~~~~~~~~~~~^^
  File "C:\Users\DELL\AppData\Local\Programs\Python\Python313\Lib\site-packages\rest_framework\request.py", line 385, in _authenticate
    user_auth_tuple = authenticator.authenticate(self)
  File "C:\Users\DELL\Desktop\projects\offline_voting_system\backend\accounts\auth.py", line 8, in authenticate
    token = auth_header.lower().split(' ')[1]
            ^^^^^^^^^^^^^^^^^
rest_framework.request.WrappedAttributeError: 'NoneType' object has no attribute 'lower'
ERROR 2025-08-29 23:32:30,721 log 10436 17068 Internal Server Error: /api/elections/elections/
Traceback (most recent call last):
  File "C:\Users\DELL\AppData\Local\Programs\Python\Python313\Lib\site-packages\rest_framework\request.py", line 74, in wrap_attributeerrors
    yield
  File "C:\Users\DELL\AppData\Local\Programs\Python\Python313\Lib\site-packages\rest_framework\request.py", line 232, in user
    self._authenticate()
    ~~~~~~~~~~~~~~~~~~^^
  File "C:\Users\DELL\AppData\Local\Programs\Python\Python313\Lib\site-packages\rest_framework\request.py", line 385, in _authenticate
    user_auth_tuple = authenticator.authenticate(self)
  File "C:\Users\DELL\Desktop\projects\offline_voting_system\backend\accounts\auth.py", line 8, in authenticate
    token = auth_header.lower().split(' ')[1]
            ^^^^^^^^^^^^^^^^^
AttributeError: 'NoneType' object has no attribute 'lower'

During handling of the above exception, another exception occurred:

Traceback (most recent call last):
  File "C:\Users\DELL\AppData\Local\Programs\Python\Python313\Lib\site-packages\django\core\handlers\exception.py", line 55, in inner
    response = get_response(request)
  File "C:\Users\DELL\AppData\Local\Programs\Python\Python313\Lib\site-packages\django\core\handlers\base.py", line 197, in _get_response
    response = wrapped_callback(request, *callback_args, **callback_kwargs)
  File "C:\Users\DELL\AppData\Local\Programs\Python\Python313\Lib\site-packages\django\views\decorators\csrf.py", line 65, in _view_wrapper
    return view_func(request, *args, **kwargs)
  File "C:\Users\DELL\AppData\Local\Programs\Python\Python313\Lib\site-packages\rest_framework\viewsets.py", line 125, in view
    return self.dispatch(request, *args, **kwargs)
           ~~~~~~~~~~~~~^^^^^^^^^^^^^^^^^^^^^^^^^^
  File "C:\Users\DELL\AppData\Local\Programs\Python\Python313\Lib\site-packages\rest_framework\views.py", line 515, in dispatch
    response = self.handle_exception(exc)
  File "C:\Users\DELL\AppData\Local\Programs\Python\Python313\Lib\site-packages\rest_framework\views.py", line 475, in handle_exception
    self.raise_uncaught_exception(exc)
    ~~~~~~~~~~~~~~~~~~~~~~~~~~~~~^^^^^
  File "C:\Users\DELL\AppData\Local\Programs\Python\Python313\Lib\site-packages\rest_framework\views.py", line 486, in raise_uncaught_exception
    raise exc
  File "C:\Users\DELL\AppData\Local\Programs\Python\Python313\Lib\site-packages\rest_framework\views.py", line 503, in dispatch
    self.initial(request, *args, **kwargs)
    ~~~~~~~~~~~~^^^^^^^^^^^^^^^^^^^^^^^^^^
  File "C:\Users\DELL\AppData\Local\Programs\Python\Python313\Lib\site-packages\rest_framework\views.py", line 420, in initial
    self.perform_authentication(request)
    ~~~~~~~~~~~~~~~~~~~~~~~~~~~^^^^^^^^^
  File "C:\Users\DELL\AppData\Local\Programs\Python\Python313\Lib\site-packages\rest_framework\views.py", line 330, in perform_authentication
    request.user
  File "C:\Users\DELL\AppData\Local\Programs\Python\Python313\Lib\site-packages\rest_framework\request.py", line 231, in user
    with wrap_attributeerrors():
         ~~~~~~~~~~~~~~~~~~~~^^
  File "C:\Users\DELL\AppData\Local\Programs\Python\Python313\Lib\contextlib.py", line 162, in __exit__
    self.gen.throw(value)
    ~~~~~~~~~~~~~~^^^^^^^
  File "C:\Users\DELL\AppData\Local\Programs\Python\Python313\Lib\site-packages\rest_framework\request.py", line 78, in wrap_attributeerrors
    raise exc.with_traceback(info[2])
  File "C:\Users\DELL\AppData\Local\Programs\Python\Python313\Lib\site-packages\rest_framework\request.py", line 74, in wrap_attributeerrors
    yield
  File "C:\Users\DELL\AppData\Local\Programs\Python\Python313\Lib\site-packages\rest_framework\request.py", line 232, in user
    self._authenticate()
    ~~~~~~~~~~~~~~~~~~^^
  File "C:\Users\DELL\AppData\Local\Programs\Python\Python313\Lib\site-packages\rest_framework\request.py", line 385, in _authenticate
    user_auth_tuple = authenticator.authenticate(self)
  File "C:\Users\DELL\Desktop\projects\offline_voting_system\backend\accounts\auth.py", line 8, in authenticate
    token = auth_header.lower().split(' ')[1]
            ^^^^^^^^^^^^^^^^^
rest_framework.request.WrappedAttributeError: 'NoneType' object has no attribute 'lower'
ERROR 2025-08-29 23:32:30,833 log 10436 4324 Internal Server Error: /api/elections/elections/
Traceback (most recent call last):
  File "C:\Users\DELL\AppData\Local\Programs\Python\Python313\Lib\site-packages\rest_framework\request.py", line 74, in wrap_attributeerrors
    yield
  File "C:\Users\DELL\AppData\Local\Programs\Python\Python313\Lib\site-packages\rest_framework\request.py", line 232, in user
    self._authenticate()
    ~~~~~~~~~~~~~~~~~~^^
  File "C:\Users\DELL\AppData\Local\Programs\Python\Python313\Lib\site-packages\rest_framework\request.py", line 385, in _authenticate
    user_auth_tuple = authenticator.authenticate(self)
  File "C:\Users\DELL\Desktop\projects\offline_voting_system\backend\accounts\auth.py", line 8, in authenticate
    token = auth_header.lower().split(' ')[1]
            ^^^^^^^^^^^^^^^^^
AttributeError: 'NoneType' object has no attribute 'lower'

During handling of the above exception, another exception occurred:

Traceback (most recent call last):
  File "C:\Users\DELL\AppData\Local\Programs\Python\Python313\Lib\site-packages\django\core\handlers\exception.py", line 55, in inner
    response = get_response(request)
  File "C:\Users\DELL\AppData\Local\Programs\Python\Python313\Lib\site-packages\django\core\handlers\base.py", line 197, in _get_response
    response = wrapped_callback(request, *callback_args, **callback_kwargs)
  File "C:\Users\DELL\AppData\Local\Programs\Python\Python313\Lib\site-packages\django\views\decorators\csrf.py", line 65, in _view_wrapper
    return view_func(request, *args, **kwargs)
  File "C:\Users\DELL\AppData\Local\Programs\Python\Python313\Lib\site-packages\rest_framework\viewsets.py", line 125, in view
    return self.dispatch(request, *args, **kwargs)
           ~~~~~~~~~~~~~^^^^^^^^^^^^^^^^^^^^^^^^^^
  File "C:\Users\DELL\AppData\Local\Programs\Python\Python313\Lib\site-packages\rest_framework\views.py", line 515, in dispatch
    response = self.handle_exception(exc)
  File "C:\Users\DELL\AppData\Local\Programs\Python\Python313\Lib\site-packages\rest_framework\views.py", line 475, in handle_exception
    self.raise_uncaught_exception(exc)
    ~~~~~~~~~~~~~~~~~~~~~~~~~~~~~^^^^^
  File "C:\Users\DELL\AppData\Local\Programs\Python\Python313\Lib\site-packages\rest_framework\views.py", line 486, in raise_uncaught_exception
    raise exc
  File "C:\Users\DELL\AppData\Local\Programs\Python\Python313\Lib\site-packages\rest_framework\views.py", line 503, in dispatch
    self.initial(request, *args, **kwargs)
    ~~~~~~~~~~~~^^^^^^^^^^^^^^^^^^^^^^^^^^
  File "C:\Users\DELL\AppData\Local\Programs\Python\Python313\Lib\site-packages\rest_framework\views.py", line 420, in initial
    self.perform_authentication(request)
    ~~~~~~~~~~~~~~~~~~~~~~~~~~~^^^^^^^^^
  File "C:\Users\DELL\AppData\Local\Programs\Python\Python313\Lib\site-packages\rest_framework\views.py", line 330, in perform_authentication
    request.user
  File "C:\Users\DELL\AppData\Local\Programs\Python\Python313\Lib\site-packages\rest_framework\request.py", line 231, in user
    with wrap_attributeerrors():
         ~~~~~~~~~~~~~~~~~~~~^^
  File "C:\Users\DELL\AppData\Local\Programs\Python\Python313\Lib\contextlib.py", line 162, in __exit__
    self.gen.throw(value)
    ~~~~~~~~~~~~~~^^^^^^^
  File "C:\Users\DELL\AppData\Local\Programs\Python\Python313\Lib\site-packages\rest_framework\request.py", line 78, in wrap_attributeerrors
    raise exc.with_traceback(info[2])
  File "C:\Users\DELL\AppData\Local\Programs\Python\Python313\Lib\site-packages\rest_framework\request.py", line 74, in wrap_attributeerrors
    yield
  File "C:\Users\DELL\AppData\Local\Programs\Python\Python313\Lib\site-packages\rest_framework\request.py", line 232, in user
    self._authenticate()
    ~~~~~~~~~~~~~~~~~~^^
  File "C:\Users\DELL\AppData\Local\Programs\Python\Python313\Lib\site-packages\rest_framework\request.py", line 385, in _authenticate
    user_auth_tuple = authenticator.authenticate(self)
  File "C:\Users\DELL\Desktop\projects\offline_voting_system\backend\accounts\auth.py", line 8, in authenticate
    token = auth_header.lower().split(' ')[1]
            ^^^^^^^^^^^^^^^^^
rest_framework.request.WrappedAttributeError: 'NoneType' object has no attribute 'lower'
ERROR 2025-08-29 23:32:31,686 log 10436 13852 Internal Server Error: /api/elections/elections/
Traceback (most recent call last):
  File "C:\Users\DELL\AppData\Local\Programs\Python\Python313\Lib\site-packages\rest_framework\request.py", line 74, in wrap_attributeerrors
    yield
  File "C:\Users\DELL\AppData\Local\Programs\Python\Python313\Lib\site-packages\rest_framework\request.py", line 232, in user
    self._authenticate()
    ~~~~~~~~~~~~~~~~~~^^
  File "C:\Users\DELL\AppData\Local\Programs\Python\Python313\Lib\site-packages\rest_framework\request.py", line 385, in _authenticate
    user_auth_tuple = authenticator.authenticate(self)
  File "C:\Users\DELL\Desktop\projects\offline_voting_system\backend\accounts\auth.py", line 8, in authenticate
    token = auth_header.lower().split(' ')[1]
            ^^^^^^^^^^^^^^^^^
AttributeError: 'NoneType' object has no attribute 'lower'

During handling of the above exception, another exception occurred:

Traceback (most recent call last):
  File "C:\Users\DELL\AppData\Local\Programs\Python\Python313\Lib\site-packages\django\core\handlers\exception.py", line 55, in inner
    response = get_response(request)
  File "C:\Users\DELL\AppData\Local\Programs\Python\Python313\Lib\site-packages\django\core\handlers\base.py", line 197, in _get_response
    response = wrapped_callback(request, *callback_args, **callback_kwargs)
  File "C:\Users\DELL\AppData\Local\Programs\Python\Python313\Lib\site-packages\django\views\decorators\csrf.py", line 65, in _view_wrapper
    return view_func(request, *args, **kwargs)
  File "C:\Users\DELL\AppData\Local\Programs\Python\Python313\Lib\site-packages\rest_framework\viewsets.py", line 125, in view
    return self.dispatch(request, *args, **kwargs)
           ~~~~~~~~~~~~~^^^^^^^^^^^^^^^^^^^^^^^^^^
  File "C:\Users\DELL\AppData\Local\Programs\Python\Python313\Lib\site-packages\rest_framework\views.py", line 515, in dispatch
    response = self.handle_exception(exc)
  File "C:\Users\DELL\AppData\Local\Programs\Python\Python313\Lib\site-packages\rest_framework\views.py", line 475, in handle_exception
    self.raise_uncaught_exception(exc)
    ~~~~~~~~~~~~~~~~~~~~~~~~~~~~~^^^^^
  File "C:\Users\DELL\AppData\Local\Programs\Python\Python313\Lib\site-packages\rest_framework\views.py", line 486, in raise_uncaught_exception
    raise exc
  File "C:\Users\DELL\AppData\Local\Programs\Python\Python313\Lib\site-packages\rest_framework\views.py", line 503, in dispatch
    self.initial(request, *args, **kwargs)
    ~~~~~~~~~~~~^^^^^^^^^^^^^^^^^^^^^^^^^^
  File "C:\Users\DELL\AppData\Local\Programs\Python\Python313\Lib\site-packages\rest_framework\views.py", line 420, in initial
    self.perform_authentication(request)
    ~~~~~~~~~~~~~~~~~~~~~~~~~~~^^^^^^^^^
  File "C:\Users\DELL\AppData\Local\Programs\Python\Python313\Lib\site-packages\rest_framework\views.py", line 330, in perform_authentication
    request.user
  File "C:\Users\DELL\AppData\Local\Programs\Python\Python313\Lib\site-packages\rest_framework\request.py", line 231, in user
    with wrap_attributeerrors():
         ~~~~~~~~~~~~~~~~~~~~^^
  File "C:\Users\DELL\AppData\Local\Programs\Python\Python313\Lib\contextlib.py", line 162, in __exit__
    self.gen.throw(value)
    ~~~~~~~~~~~~~~^^^^^^^
  File "C:\Users\DELL\AppData\Local\Programs\Python\Python313\Lib\site-packages\rest_framework\request.py", line 78, in wrap_attributeerrors
    raise exc.with_traceback(info[2])
  File "C:\Users\DELL\AppData\Local\Programs\Python\Python313\Lib\site-packages\rest_framework\request.py", line 74, in wrap_attributeerrors
    yield
  File "C:\Users\DELL\AppData\Local\Programs\Python\Python313\Lib\site-packages\rest_framework\request.py", line 232, in user
    self._authenticate()
    ~~~~~~~~~~~~~~~~~~^^
  File "C:\Users\DELL\AppData\Local\Programs\Python\Python313\Lib\site-packages\rest_framework\request.py", line 385, in _authenticate
    user_auth_tuple = authenticator.authenticate(self)
  File "C:\Users\DELL\Desktop\projects\offline_voting_system\backend\accounts\auth.py", line 8, in authenticate
    token = auth_header.lower().split(' ')[1]
            ^^^^^^^^^^^^^^^^^
rest_framework.request.WrappedAttributeError: 'NoneType' object has no attribute 'lower'
ERROR 2025-08-29 23:32:31,697 log 10436 13640 Internal Server Error: /api/elections/elections/
Traceback (most recent call last):
  File "C:\Users\DELL\AppData\Local\Programs\Python\Python313\Lib\site-packages\rest_framework\request.py", line 74, in wrap_attributeerrors
    yield
  File "C:\Users\DELL\AppData\Local\Programs\Python\Python313\Lib\site-packages\rest_framework\request.py", line 232, in user
    self._authenticate()
    ~~~~~~~~~~~~~~~~~~^^
  File "C:\Users\DELL\AppData\Local\Programs\Python\Python313\Lib\site-packages\rest_framework\request.py", line 385, in _authenticate
    user_auth_tuple = authenticator.authenticate(self)
  File "C:\Users\DELL\Desktop\projects\offline_voting_system\backend\accounts\auth.py", line 8, in authenticate
    token = auth_header.lower().split(' ')[1]
            ^^^^^^^^^^^^^^^^^
AttributeError: 'NoneType' object has no attribute 'lower'

During handling of the above exception, another exception occurred:

Traceback (most recent call last):
  File "C:\Users\DELL\AppData\Local\Programs\Python\Python313\Lib\site-packages\django\core\handlers\exception.py", line 55, in inner
    response = get_response(request)
  File "C:\Users\DELL\AppData\Local\Programs\Python\Python313\Lib\site-packages\django\core\handlers\base.py", line 197, in _get_response
    response = wrapped_callback(request, *callback_args, **callback_kwargs)
  File "C:\Users\DELL\AppData\Local\Programs\Python\Python313\Lib\site-packages\django\views\decorators\csrf.py", line 65, in _view_wrapper
    return view_func(request, *args, **kwargs)
  File "C:\Users\DELL\AppData\Local\Programs\Python\Python313\Lib\site-packages\rest_framework\viewsets.py", line 125, in view
    return self.dispatch(request, *args, **kwargs)
           ~~~~~~~~~~~~~^^^^^^^^^^^^^^^^^^^^^^^^^^
  File "C:\Users\DELL\AppData\Local\Programs\Python\Python313\Lib\site-packages\rest_framework\views.py", line 515, in dispatch
    response = self.handle_exception(exc)
  File "C:\Users\DELL\AppData\Local\Programs\Python\Python313\Lib\site-packages\rest_framework\views.py", line 475, in handle_exception
    self.raise_uncaught_exception(exc)
    ~~~~~~~~~~~~~~~~~~~~~~~~~~~~~^^^^^
  File "C:\Users\DELL\AppData\Local\Programs\Python\Python313\Lib\site-packages\rest_framework\views.py", line 486, in raise_uncaught_exception
    raise exc
  File "C:\Users\DELL\AppData\Local\Programs\Python\Python313\Lib\site-packages\rest_framework\views.py", line 503, in dispatch
    self.initial(request, *args, **kwargs)
    ~~~~~~~~~~~~^^^^^^^^^^^^^^^^^^^^^^^^^^
  File "C:\Users\DELL\AppData\Local\Programs\Python\Python313\Lib\site-packages\rest_framework\views.py", line 420, in initial
    self.perform_authentication(request)
    ~~~~~~~~~~~~~~~~~~~~~~~~~~~^^^^^^^^^
  File "C:\Users\DELL\AppData\Local\Programs\Python\Python313\Lib\site-packages\rest_framework\views.py", line 330, in perform_authentication
    request.user
  File "C:\Users\DELL\AppData\Local\Programs\Python\Python313\Lib\site-packages\rest_framework\request.py", line 231, in user
    with wrap_attributeerrors():
         ~~~~~~~~~~~~~~~~~~~~^^
  File "C:\Users\DELL\AppData\Local\Programs\Python\Python313\Lib\contextlib.py", line 162, in __exit__
    self.gen.throw(value)
    ~~~~~~~~~~~~~~^^^^^^^
  File "C:\Users\DELL\AppData\Local\Programs\Python\Python313\Lib\site-packages\rest_framework\request.py", line 78, in wrap_attributeerrors
    raise exc.with_traceback(info[2])
  File "C:\Users\DELL\AppData\Local\Programs\Python\Python313\Lib\site-packages\rest_framework\request.py", line 74, in wrap_attributeerrors
    yield
  File "C:\Users\DELL\AppData\Local\Programs\Python\Python313\Lib\site-packages\rest_framework\request.py", line 232, in user
    self._authenticate()
    ~~~~~~~~~~~~~~~~~~^^
  File "C:\Users\DELL\AppData\Local\Programs\Python\Python313\Lib\site-packages\rest_framework\request.py", line 385, in _authenticate
    user_auth_tuple = authenticator.authenticate(self)
  File "C:\Users\DELL\Desktop\projects\offline_voting_system\backend\accounts\auth.py", line 8, in authenticate
    token = auth_header.lower().split(' ')[1]
            ^^^^^^^^^^^^^^^^^
rest_framework.request.WrappedAttributeError: 'NoneType' object has no attribute 'lower'
ERROR 2025-08-29 23:32:32,551 log 10436 8364 Internal Server Error: /api/elections/elections/
Traceback (most recent call last):
  File "C:\Users\DELL\AppData\Local\Programs\Python\Python313\Lib\site-packages\rest_framework\request.py", line 74, in wrap_attributeerrors
    yield
  File "C:\Users\DELL\AppData\Local\Programs\Python\Python313\Lib\site-packages\rest_framework\request.py", line 232, in user
    self._authenticate()
    ~~~~~~~~~~~~~~~~~~^^
  File "C:\Users\DELL\AppData\Local\Programs\Python\Python313\Lib\site-packages\rest_framework\request.py", line 385, in _authenticate
    user_auth_tuple = authenticator.authenticate(self)
  File "C:\Users\DELL\Desktop\projects\offline_voting_system\backend\accounts\auth.py", line 8, in authenticate
    token = auth_header.lower().split(' ')[1]
            ^^^^^^^^^^^^^^^^^
AttributeError: 'NoneType' object has no attribute 'lower'

During handling of the above exception, another exception occurred:

Traceback (most recent call last):
  File "C:\Users\DELL\AppData\Local\Programs\Python\Python313\Lib\site-packages\django\core\handlers\exception.py", line 55, in inner
    response = get_response(request)
  File "C:\Users\DELL\AppData\Local\Programs\Python\Python313\Lib\site-packages\django\core\handlers\base.py", line 197, in _get_response
    response = wrapped_callback(request, *callback_args, **callback_kwargs)
  File "C:\Users\DELL\AppData\Local\Programs\Python\Python313\Lib\site-packages\django\views\decorators\csrf.py", line 65, in _view_wrapper
    return view_func(request, *args, **kwargs)
  File "C:\Users\DELL\AppData\Local\Programs\Python\Python313\Lib\site-packages\rest_framework\viewsets.py", line 125, in view
    return self.dispatch(request, *args, **kwargs)
           ~~~~~~~~~~~~~^^^^^^^^^^^^^^^^^^^^^^^^^^
  File "C:\Users\DELL\AppData\Local\Programs\Python\Python313\Lib\site-packages\rest_framework\views.py", line 515, in dispatch
    response = self.handle_exception(exc)
  File "C:\Users\DELL\AppData\Local\Programs\Python\Python313\Lib\site-packages\rest_framework\views.py", line 475, in handle_exception
    self.raise_uncaught_exception(exc)
    ~~~~~~~~~~~~~~~~~~~~~~~~~~~~~^^^^^
  File "C:\Users\DELL\AppData\Local\Programs\Python\Python313\Lib\site-packages\rest_framework\views.py", line 486, in raise_uncaught_exception
    raise exc
  File "C:\Users\DELL\AppData\Local\Programs\Python\Python313\Lib\site-packages\rest_framework\views.py", line 503, in dispatch
    self.initial(request, *args, **kwargs)
    ~~~~~~~~~~~~^^^^^^^^^^^^^^^^^^^^^^^^^^
  File "C:\Users\DELL\AppData\Local\Programs\Python\Python313\Lib\site-packages\rest_framework\views.py", line 420, in initial
    self.perform_authentication(request)
    ~~~~~~~~~~~~~~~~~~~~~~~~~~~^^^^^^^^^
  File "C:\Users\DELL\AppData\Local\Programs\Python\Python313\Lib\site-packages\rest_framework\views.py", line 330, in perform_authentication
    request.user
  File "C:\Users\DELL\AppData\Local\Programs\Python\Python313\Lib\site-packages\rest_framework\request.py", line 231, in user
    with wrap_attributeerrors():
         ~~~~~~~~~~~~~~~~~~~~^^
  File "C:\Users\DELL\AppData\Local\Programs\Python\Python313\Lib\contextlib.py", line 162, in __exit__
    self.gen.throw(value)
    ~~~~~~~~~~~~~~^^^^^^^
  File "C:\Users\DELL\AppData\Local\Programs\Python\Python313\Lib\site-packages\rest_framework\request.py", line 78, in wrap_attributeerrors
    raise exc.with_traceback(info[2])
  File "C:\Users\DELL\AppData\Local\Programs\Python\Python313\Lib\site-packages\rest_framework\request.py", line 74, in wrap_attributeerrors
    yield
  File "C:\Users\DELL\AppData\Local\Programs\Python\Python313\Lib\site-packages\rest_framework\request.py", line 232, in user
    self._authenticate()
    ~~~~~~~~~~~~~~~~~~^^
  File "C:\Users\DELL\AppData\Local\Programs\Python\Python313\Lib\site-packages\rest_framework\request.py", line 385, in _authenticate
    user_auth_tuple = authenticator.authenticate(self)
  File "C:\Users\DELL\Desktop\projects\offline_voting_system\backend\accounts\auth.py", line 8, in authenticate
    token = auth_header.lower().split(' ')[1]
            ^^^^^^^^^^^^^^^^^
rest_framework.request.WrappedAttributeError: 'NoneType' object has no attribute 'lower'
ERROR 2025-08-29 23:34:08,422 log 10436 11868 Internal Server Error: /api/elections/elections/
Traceback (most recent call last):
  File "C:\Users\DELL\AppData\Local\Programs\Python\Python313\Lib\site-packages\rest_framework\request.py", line 74, in wrap_attributeerrors
    yield
  File "C:\Users\DELL\AppData\Local\Programs\Python\Python313\Lib\site-packages\rest_framework\request.py", line 232, in user
    self._authenticate()
    ~~~~~~~~~~~~~~~~~~^^
  File "C:\Users\DELL\AppData\Local\Programs\Python\Python313\Lib\site-packages\rest_framework\request.py", line 385, in _authenticate
    user_auth_tuple = authenticator.authenticate(self)
  File "C:\Users\DELL\Desktop\projects\offline_voting_system\backend\accounts\auth.py", line 8, in authenticate
    token = auth_header.lower().split(' ')[1]
            ^^^^^^^^^^^^^^^^^
AttributeError: 'NoneType' object has no attribute 'lower'

During handling of the above exception, another exception occurred:

Traceback (most recent call last):
  File "C:\Users\DELL\AppData\Local\Programs\Python\Python313\Lib\site-packages\django\core\handlers\exception.py", line 55, in inner
    response = get_response(request)
  File "C:\Users\DELL\AppData\Local\Programs\Python\Python313\Lib\site-packages\django\core\handlers\base.py", line 197, in _get_response
    response = wrapped_callback(request, *callback_args, **callback_kwargs)
  File "C:\Users\DELL\AppData\Local\Programs\Python\Python313\Lib\site-packages\django\views\decorators\csrf.py", line 65, in _view_wrapper
    return view_func(request, *args, **kwargs)
  File "C:\Users\DELL\AppData\Local\Programs\Python\Python313\Lib\site-packages\rest_framework\viewsets.py", line 125, in view
    return self.dispatch(request, *args, **kwargs)
           ~~~~~~~~~~~~~^^^^^^^^^^^^^^^^^^^^^^^^^^
  File "C:\Users\DELL\AppData\Local\Programs\Python\Python313\Lib\site-packages\rest_framework\views.py", line 515, in dispatch
    response = self.handle_exception(exc)
  File "C:\Users\DELL\AppData\Local\Programs\Python\Python313\Lib\site-packages\rest_framework\views.py", line 475, in handle_exception
    self.raise_uncaught_exception(exc)
    ~~~~~~~~~~~~~~~~~~~~~~~~~~~~~^^^^^
  File "C:\Users\DELL\AppData\Local\Programs\Python\Python313\Lib\site-packages\rest_framework\views.py", line 486, in raise_uncaught_exception
    raise exc
  File "C:\Users\DELL\AppData\Local\Programs\Python\Python313\Lib\site-packages\rest_framework\views.py", line 503, in dispatch
    self.initial(request, *args, **kwargs)
    ~~~~~~~~~~~~^^^^^^^^^^^^^^^^^^^^^^^^^^
  File "C:\Users\DELL\AppData\Local\Programs\Python\Python313\Lib\site-packages\rest_framework\views.py", line 420, in initial
    self.perform_authentication(request)
    ~~~~~~~~~~~~~~~~~~~~~~~~~~~^^^^^^^^^
  File "C:\Users\DELL\AppData\Local\Programs\Python\Python313\Lib\site-packages\rest_framework\views.py", line 330, in perform_authentication
    request.user
  File "C:\Users\DELL\AppData\Local\Programs\Python\Python313\Lib\site-packages\rest_framework\request.py", line 231, in user
    with wrap_attributeerrors():
         ~~~~~~~~~~~~~~~~~~~~^^
  File "C:\Users\DELL\AppData\Local\Programs\Python\Python313\Lib\contextlib.py", line 162, in __exit__
    self.gen.throw(value)
    ~~~~~~~~~~~~~~^^^^^^^
  File "C:\Users\DELL\AppData\Local\Programs\Python\Python313\Lib\site-packages\rest_framework\request.py", line 78, in wrap_attributeerrors
    raise exc.with_traceback(info[2])
  File "C:\Users\DELL\AppData\Local\Programs\Python\Python313\Lib\site-packages\rest_framework\request.py", line 74, in wrap_attributeerrors
    yield
  File "C:\Users\DELL\AppData\Local\Programs\Python\Python313\Lib\site-packages\rest_framework\request.py", line 232, in user
    self._authenticate()
    ~~~~~~~~~~~~~~~~~~^^
  File "C:\Users\DELL\AppData\Local\Programs\Python\Python313\Lib\site-packages\rest_framework\request.py", line 385, in _authenticate
    user_auth_tuple = authenticator.authenticate(self)
  File "C:\Users\DELL\Desktop\projects\offline_voting_system\backend\accounts\auth.py", line 8, in authenticate
    token = auth_header.lower().split(' ')[1]
            ^^^^^^^^^^^^^^^^^
rest_framework.request.WrappedAttributeError: 'NoneType' object has no attribute 'lower'
ERROR 2025-08-30 11:28:53,950 log 11612 12360 Internal Server Error: /api/auth/users/
Traceback (most recent call last):
  File "C:\Users\DELL\AppData\Local\Programs\Python\Python313\Lib\site-packages\django\core\handlers\exception.py", line 55, in inner
    response = get_response(request)
  File "C:\Users\DELL\AppData\Local\Programs\Python\Python313\Lib\site-packages\django\core\handlers\base.py", line 197, in _get_response
    response = wrapped_callback(request, *callback_args, **callback_kwargs)
  File "C:\Users\DELL\AppData\Local\Programs\Python\Python313\Lib\site-packages\django\views\decorators\csrf.py", line 65, in _view_wrapper
    return view_func(request, *args, **kwargs)
  File "C:\Users\DELL\AppData\Local\Programs\Python\Python313\Lib\site-packages\rest_framework\viewsets.py", line 125, in view
    return self.dispatch(request, *args, **kwargs)
           ~~~~~~~~~~~~~^^^^^^^^^^^^^^^^^^^^^^^^^^
  File "C:\Users\DELL\AppData\Local\Programs\Python\Python313\Lib\site-packages\rest_framework\views.py", line 515, in dispatch
    response = self.handle_exception(exc)
  File "C:\Users\DELL\AppData\Local\Programs\Python\Python313\Lib\site-packages\rest_framework\views.py", line 475, in handle_exception
    self.raise_uncaught_exception(exc)
    ~~~~~~~~~~~~~~~~~~~~~~~~~~~~~^^^^^
  File "C:\Users\DELL\AppData\Local\Programs\Python\Python313\Lib\site-packages\rest_framework\views.py", line 486, in raise_uncaught_exception
    raise exc
  File "C:\Users\DELL\AppData\Local\Programs\Python\Python313\Lib\site-packages\rest_framework\views.py", line 512, in dispatch
    response = handler(request, *args, **kwargs)
  File "C:\Users\DELL\AppData\Local\Programs\Python\Python313\Lib\site-packages\rest_framework\mixins.py", line 19, in create
    self.perform_create(serializer)
    ~~~~~~~~~~~~~~~~~~~^^^^^^^^^^^^
  File "C:\Users\DELL\AppData\Local\Programs\Python\Python313\Lib\site-packages\rest_framework\mixins.py", line 24, in perform_create
    serializer.save()
    ~~~~~~~~~~~~~~~^^
  File "C:\Users\DELL\AppData\Local\Programs\Python\Python313\Lib\site-packages\rest_framework\serializers.py", line 210, in save
    self.instance = self.create(validated_data)
                    ~~~~~~~~~~~^^^^^^^^^^^^^^^^
  File "C:\Users\DELL\Desktop\projects\offline_voting_system\backend\accounts\serializers.py", line 17, in create
    user = User.objects.create_user(**validated_data)
TypeError: CustomUserManager.create_user() missing 1 required positional argument: 'username'
ERROR 2025-08-30 11:29:55,966 log 11612 10040 Internal Server Error: /api/auth/users/
Traceback (most recent call last):
  File "C:\Users\DELL\AppData\Local\Programs\Python\Python313\Lib\site-packages\django\core\handlers\exception.py", line 55, in inner
    response = get_response(request)
  File "C:\Users\DELL\AppData\Local\Programs\Python\Python313\Lib\site-packages\django\core\handlers\base.py", line 197, in _get_response
    response = wrapped_callback(request, *callback_args, **callback_kwargs)
  File "C:\Users\DELL\AppData\Local\Programs\Python\Python313\Lib\site-packages\django\views\decorators\csrf.py", line 65, in _view_wrapper
    return view_func(request, *args, **kwargs)
  File "C:\Users\DELL\AppData\Local\Programs\Python\Python313\Lib\site-packages\rest_framework\viewsets.py", line 125, in view
    return self.dispatch(request, *args, **kwargs)
           ~~~~~~~~~~~~~^^^^^^^^^^^^^^^^^^^^^^^^^^
  File "C:\Users\DELL\AppData\Local\Programs\Python\Python313\Lib\site-packages\rest_framework\views.py", line 515, in dispatch
    response = self.handle_exception(exc)
  File "C:\Users\DELL\AppData\Local\Programs\Python\Python313\Lib\site-packages\rest_framework\views.py", line 475, in handle_exception
    self.raise_uncaught_exception(exc)
    ~~~~~~~~~~~~~~~~~~~~~~~~~~~~~^^^^^
  File "C:\Users\DELL\AppData\Local\Programs\Python\Python313\Lib\site-packages\rest_framework\views.py", line 486, in raise_uncaught_exception
    raise exc
  File "C:\Users\DELL\AppData\Local\Programs\Python\Python313\Lib\site-packages\rest_framework\views.py", line 512, in dispatch
    response = handler(request, *args, **kwargs)
  File "C:\Users\DELL\AppData\Local\Programs\Python\Python313\Lib\site-packages\rest_framework\mixins.py", line 19, in create
    self.perform_create(serializer)
    ~~~~~~~~~~~~~~~~~~~^^^^^^^^^^^^
  File "C:\Users\DELL\AppData\Local\Programs\Python\Python313\Lib\site-packages\rest_framework\mixins.py", line 24, in perform_create
    serializer.save()
    ~~~~~~~~~~~~~~~^^
  File "C:\Users\DELL\AppData\Local\Programs\Python\Python313\Lib\site-packages\rest_framework\serializers.py", line 210, in save
    self.instance = self.create(validated_data)
                    ~~~~~~~~~~~^^^^^^^^^^^^^^^^
  File "C:\Users\DELL\Desktop\projects\offline_voting_system\backend\accounts\serializers.py", line 17, in create
    user = User.objects.create_user(**validated_data)
TypeError: CustomUserManager.create_user() missing 1 required positional argument: 'username'
ERROR 2025-08-30 11:30:06,177 log 11612 10040 Internal Server Error: /api/auth/users/
Traceback (most recent call last):
  File "C:\Users\DELL\AppData\Local\Programs\Python\Python313\Lib\site-packages\django\core\handlers\exception.py", line 55, in inner
    response = get_response(request)
  File "C:\Users\DELL\AppData\Local\Programs\Python\Python313\Lib\site-packages\django\core\handlers\base.py", line 197, in _get_response
    response = wrapped_callback(request, *callback_args, **callback_kwargs)
  File "C:\Users\DELL\AppData\Local\Programs\Python\Python313\Lib\site-packages\django\views\decorators\csrf.py", line 65, in _view_wrapper
    return view_func(request, *args, **kwargs)
  File "C:\Users\DELL\AppData\Local\Programs\Python\Python313\Lib\site-packages\rest_framework\viewsets.py", line 125, in view
    return self.dispatch(request, *args, **kwargs)
           ~~~~~~~~~~~~~^^^^^^^^^^^^^^^^^^^^^^^^^^
  File "C:\Users\DELL\AppData\Local\Programs\Python\Python313\Lib\site-packages\rest_framework\views.py", line 515, in dispatch
    response = self.handle_exception(exc)
  File "C:\Users\DELL\AppData\Local\Programs\Python\Python313\Lib\site-packages\rest_framework\views.py", line 475, in handle_exception
    self.raise_uncaught_exception(exc)
    ~~~~~~~~~~~~~~~~~~~~~~~~~~~~~^^^^^
  File "C:\Users\DELL\AppData\Local\Programs\Python\Python313\Lib\site-packages\rest_framework\views.py", line 486, in raise_uncaught_exception
    raise exc
  File "C:\Users\DELL\AppData\Local\Programs\Python\Python313\Lib\site-packages\rest_framework\views.py", line 512, in dispatch
    response = handler(request, *args, **kwargs)
  File "C:\Users\DELL\AppData\Local\Programs\Python\Python313\Lib\site-packages\rest_framework\mixins.py", line 19, in create
    self.perform_create(serializer)
    ~~~~~~~~~~~~~~~~~~~^^^^^^^^^^^^
  File "C:\Users\DELL\AppData\Local\Programs\Python\Python313\Lib\site-packages\rest_framework\mixins.py", line 24, in perform_create
    serializer.save()
    ~~~~~~~~~~~~~~~^^
  File "C:\Users\DELL\AppData\Local\Programs\Python\Python313\Lib\site-packages\rest_framework\serializers.py", line 210, in save
    self.instance = self.create(validated_data)
                    ~~~~~~~~~~~^^^^^^^^^^^^^^^^
  File "C:\Users\DELL\Desktop\projects\offline_voting_system\backend\accounts\serializers.py", line 17, in create
    user = User.objects.create_user(**validated_data)
TypeError: CustomUserManager.create_user() missing 1 required positional argument: 'username'
ERROR 2025-08-30 11:33:59,582 log 11612 10040 Internal Server Error: /api/auth/users/
Traceback (most recent call last):
  File "C:\Users\DELL\AppData\Local\Programs\Python\Python313\Lib\site-packages\django\core\handlers\exception.py", line 55, in inner
    response = get_response(request)
  File "C:\Users\DELL\AppData\Local\Programs\Python\Python313\Lib\site-packages\django\core\handlers\base.py", line 197, in _get_response
    response = wrapped_callback(request, *callback_args, **callback_kwargs)
  File "C:\Users\DELL\AppData\Local\Programs\Python\Python313\Lib\site-packages\django\views\decorators\csrf.py", line 65, in _view_wrapper
    return view_func(request, *args, **kwargs)
  File "C:\Users\DELL\AppData\Local\Programs\Python\Python313\Lib\site-packages\rest_framework\viewsets.py", line 125, in view
    return self.dispatch(request, *args, **kwargs)
           ~~~~~~~~~~~~~^^^^^^^^^^^^^^^^^^^^^^^^^^
  File "C:\Users\DELL\AppData\Local\Programs\Python\Python313\Lib\site-packages\rest_framework\views.py", line 515, in dispatch
    response = self.handle_exception(exc)
  File "C:\Users\DELL\AppData\Local\Programs\Python\Python313\Lib\site-packages\rest_framework\views.py", line 475, in handle_exception
    self.raise_uncaught_exception(exc)
    ~~~~~~~~~~~~~~~~~~~~~~~~~~~~~^^^^^
  File "C:\Users\DELL\AppData\Local\Programs\Python\Python313\Lib\site-packages\rest_framework\views.py", line 486, in raise_uncaught_exception
    raise exc
  File "C:\Users\DELL\AppData\Local\Programs\Python\Python313\Lib\site-packages\rest_framework\views.py", line 512, in dispatch
    response = handler(request, *args, **kwargs)
  File "C:\Users\DELL\AppData\Local\Programs\Python\Python313\Lib\site-packages\rest_framework\mixins.py", line 19, in create
    self.perform_create(serializer)
    ~~~~~~~~~~~~~~~~~~~^^^^^^^^^^^^
  File "C:\Users\DELL\AppData\Local\Programs\Python\Python313\Lib\site-packages\rest_framework\mixins.py", line 24, in perform_create
    serializer.save()
    ~~~~~~~~~~~~~~~^^
  File "C:\Users\DELL\AppData\Local\Programs\Python\Python313\Lib\site-packages\rest_framework\serializers.py", line 210, in save
    self.instance = self.create(validated_data)
                    ~~~~~~~~~~~^^^^^^^^^^^^^^^^
  File "C:\Users\DELL\Desktop\projects\offline_voting_system\backend\accounts\serializers.py", line 17, in create
    user = User.objects.create_user(**validated_data)
TypeError: CustomUserManager.create_user() missing 1 required positional argument: 'username'
ERROR 2025-08-30 11:37:40,495 log 11612 15228 Internal Server Error: /api/auth/users/
Traceback (most recent call last):
  File "C:\Users\DELL\AppData\Local\Programs\Python\Python313\Lib\site-packages\django\core\handlers\exception.py", line 55, in inner
    response = get_response(request)
  File "C:\Users\DELL\AppData\Local\Programs\Python\Python313\Lib\site-packages\django\core\handlers\base.py", line 197, in _get_response
    response = wrapped_callback(request, *callback_args, **callback_kwargs)
  File "C:\Users\DELL\AppData\Local\Programs\Python\Python313\Lib\site-packages\django\views\decorators\csrf.py", line 65, in _view_wrapper
    return view_func(request, *args, **kwargs)
  File "C:\Users\DELL\AppData\Local\Programs\Python\Python313\Lib\site-packages\rest_framework\viewsets.py", line 125, in view
    return self.dispatch(request, *args, **kwargs)
           ~~~~~~~~~~~~~^^^^^^^^^^^^^^^^^^^^^^^^^^
  File "C:\Users\DELL\AppData\Local\Programs\Python\Python313\Lib\site-packages\rest_framework\views.py", line 515, in dispatch
    response = self.handle_exception(exc)
  File "C:\Users\DELL\AppData\Local\Programs\Python\Python313\Lib\site-packages\rest_framework\views.py", line 475, in handle_exception
    self.raise_uncaught_exception(exc)
    ~~~~~~~~~~~~~~~~~~~~~~~~~~~~~^^^^^
  File "C:\Users\DELL\AppData\Local\Programs\Python\Python313\Lib\site-packages\rest_framework\views.py", line 486, in raise_uncaught_exception
    raise exc
  File "C:\Users\DELL\AppData\Local\Programs\Python\Python313\Lib\site-packages\rest_framework\views.py", line 512, in dispatch
    response = handler(request, *args, **kwargs)
  File "C:\Users\DELL\AppData\Local\Programs\Python\Python313\Lib\site-packages\rest_framework\mixins.py", line 19, in create
    self.perform_create(serializer)
    ~~~~~~~~~~~~~~~~~~~^^^^^^^^^^^^
  File "C:\Users\DELL\AppData\Local\Programs\Python\Python313\Lib\site-packages\rest_framework\mixins.py", line 24, in perform_create
    serializer.save()
    ~~~~~~~~~~~~~~~^^
  File "C:\Users\DELL\AppData\Local\Programs\Python\Python313\Lib\site-packages\rest_framework\serializers.py", line 210, in save
    self.instance = self.create(validated_data)
                    ~~~~~~~~~~~^^^^^^^^^^^^^^^^
  File "C:\Users\DELL\Desktop\projects\offline_voting_system\backend\accounts\serializers.py", line 17, in create
    user = User.objects.create_user(**validated_data)
TypeError: CustomUserManager.create_user() missing 1 required positional argument: 'username'
ERROR 2025-08-30 11:39:32,292 log 11612 14256 Internal Server Error: /api/auth/users/
Traceback (most recent call last):
  File "C:\Users\DELL\AppData\Local\Programs\Python\Python313\Lib\site-packages\django\core\handlers\exception.py", line 55, in inner
    response = get_response(request)
  File "C:\Users\DELL\AppData\Local\Programs\Python\Python313\Lib\site-packages\django\core\handlers\base.py", line 197, in _get_response
    response = wrapped_callback(request, *callback_args, **callback_kwargs)
  File "C:\Users\DELL\AppData\Local\Programs\Python\Python313\Lib\site-packages\django\views\decorators\csrf.py", line 65, in _view_wrapper
    return view_func(request, *args, **kwargs)
  File "C:\Users\DELL\AppData\Local\Programs\Python\Python313\Lib\site-packages\rest_framework\viewsets.py", line 125, in view
    return self.dispatch(request, *args, **kwargs)
           ~~~~~~~~~~~~~^^^^^^^^^^^^^^^^^^^^^^^^^^
  File "C:\Users\DELL\AppData\Local\Programs\Python\Python313\Lib\site-packages\rest_framework\views.py", line 515, in dispatch
    response = self.handle_exception(exc)
  File "C:\Users\DELL\AppData\Local\Programs\Python\Python313\Lib\site-packages\rest_framework\views.py", line 475, in handle_exception
    self.raise_uncaught_exception(exc)
    ~~~~~~~~~~~~~~~~~~~~~~~~~~~~~^^^^^
  File "C:\Users\DELL\AppData\Local\Programs\Python\Python313\Lib\site-packages\rest_framework\views.py", line 486, in raise_uncaught_exception
    raise exc
  File "C:\Users\DELL\AppData\Local\Programs\Python\Python313\Lib\site-packages\rest_framework\views.py", line 512, in dispatch
    response = handler(request, *args, **kwargs)
  File "C:\Users\DELL\AppData\Local\Programs\Python\Python313\Lib\site-packages\rest_framework\mixins.py", line 19, in create
    self.perform_create(serializer)
    ~~~~~~~~~~~~~~~~~~~^^^^^^^^^^^^
  File "C:\Users\DELL\AppData\Local\Programs\Python\Python313\Lib\site-packages\rest_framework\mixins.py", line 24, in perform_create
    serializer.save()
    ~~~~~~~~~~~~~~~^^
  File "C:\Users\DELL\AppData\Local\Programs\Python\Python313\Lib\site-packages\rest_framework\serializers.py", line 210, in save
    self.instance = self.create(validated_data)
                    ~~~~~~~~~~~^^^^^^^^^^^^^^^^
  File "C:\Users\DELL\Desktop\projects\offline_voting_system\backend\accounts\serializers.py", line 17, in create
    user = User.objects.create_user(**validated_data)
TypeError: CustomUserManager.create_user() missing 1 required positional argument: 'username'
ERROR 2025-08-30 12:46:29,192 log 11612 13108 Internal Server Error: /api/auth/login/
Traceback (most recent call last):
  File "C:\Users\DELL\AppData\Local\Programs\Python\Python313\Lib\site-packages\rest_framework\request.py", line 74, in wrap_attributeerrors
    yield
  File "C:\Users\DELL\AppData\Local\Programs\Python\Python313\Lib\site-packages\rest_framework\request.py", line 232, in user
    self._authenticate()
    ~~~~~~~~~~~~~~~~~~^^
  File "C:\Users\DELL\AppData\Local\Programs\Python\Python313\Lib\site-packages\rest_framework\request.py", line 385, in _authenticate
    user_auth_tuple = authenticator.authenticate(self)
  File "C:\Users\DELL\Desktop\projects\offline_voting_system\backend\accounts\auth.py", line 8, in authenticate
    token = auth_header.lower().split(' ')[1]
            ^^^^^^^^^^^^^^^^^
AttributeError: 'NoneType' object has no attribute 'lower'

During handling of the above exception, another exception occurred:

Traceback (most recent call last):
  File "C:\Users\DELL\AppData\Local\Programs\Python\Python313\Lib\site-packages\django\core\handlers\exception.py", line 55, in inner
    response = get_response(request)
  File "C:\Users\DELL\AppData\Local\Programs\Python\Python313\Lib\site-packages\django\core\handlers\base.py", line 197, in _get_response
    response = wrapped_callback(request, *callback_args, **callback_kwargs)
  File "C:\Users\DELL\AppData\Local\Programs\Python\Python313\Lib\site-packages\django\views\decorators\csrf.py", line 65, in _view_wrapper
    return view_func(request, *args, **kwargs)
  File "C:\Users\DELL\AppData\Local\Programs\Python\Python313\Lib\site-packages\django\views\generic\base.py", line 105, in view
    return self.dispatch(request, *args, **kwargs)
           ~~~~~~~~~~~~~^^^^^^^^^^^^^^^^^^^^^^^^^^
  File "C:\Users\DELL\AppData\Local\Programs\Python\Python313\Lib\site-packages\rest_framework\views.py", line 515, in dispatch
    response = self.handle_exception(exc)
  File "C:\Users\DELL\AppData\Local\Programs\Python\Python313\Lib\site-packages\rest_framework\views.py", line 475, in handle_exception
    self.raise_uncaught_exception(exc)
    ~~~~~~~~~~~~~~~~~~~~~~~~~~~~~^^^^^
  File "C:\Users\DELL\AppData\Local\Programs\Python\Python313\Lib\site-packages\rest_framework\views.py", line 486, in raise_uncaught_exception
    raise exc
  File "C:\Users\DELL\AppData\Local\Programs\Python\Python313\Lib\site-packages\rest_framework\views.py", line 503, in dispatch
    self.initial(request, *args, **kwargs)
    ~~~~~~~~~~~~^^^^^^^^^^^^^^^^^^^^^^^^^^
  File "C:\Users\DELL\AppData\Local\Programs\Python\Python313\Lib\site-packages\rest_framework\views.py", line 420, in initial
    self.perform_authentication(request)
    ~~~~~~~~~~~~~~~~~~~~~~~~~~~^^^^^^^^^
  File "C:\Users\DELL\AppData\Local\Programs\Python\Python313\Lib\site-packages\rest_framework\views.py", line 330, in perform_authentication
    request.user
  File "C:\Users\DELL\AppData\Local\Programs\Python\Python313\Lib\site-packages\rest_framework\request.py", line 231, in user
    with wrap_attributeerrors():
         ~~~~~~~~~~~~~~~~~~~~^^
  File "C:\Users\DELL\AppData\Local\Programs\Python\Python313\Lib\contextlib.py", line 162, in __exit__
    self.gen.throw(value)
    ~~~~~~~~~~~~~~^^^^^^^
  File "C:\Users\DELL\AppData\Local\Programs\Python\Python313\Lib\site-packages\rest_framework\request.py", line 78, in wrap_attributeerrors
    raise exc.with_traceback(info[2])
  File "C:\Users\DELL\AppData\Local\Programs\Python\Python313\Lib\site-packages\rest_framework\request.py", line 74, in wrap_attributeerrors
    yield
  File "C:\Users\DELL\AppData\Local\Programs\Python\Python313\Lib\site-packages\rest_framework\request.py", line 232, in user
    self._authenticate()
    ~~~~~~~~~~~~~~~~~~^^
  File "C:\Users\DELL\AppData\Local\Programs\Python\Python313\Lib\site-packages\rest_framework\request.py", line 385, in _authenticate
    user_auth_tuple = authenticator.authenticate(self)
  File "C:\Users\DELL\Desktop\projects\offline_voting_system\backend\accounts\auth.py", line 8, in authenticate
    token = auth_header.lower().split(' ')[1]
            ^^^^^^^^^^^^^^^^^
rest_framework.request.WrappedAttributeError: 'NoneType' object has no attribute 'lower'
ERROR 2025-08-30 12:46:45,767 log 11612 9076 Internal Server Error: /api/auth/login/
Traceback (most recent call last):
  File "C:\Users\DELL\AppData\Local\Programs\Python\Python313\Lib\site-packages\rest_framework\request.py", line 74, in wrap_attributeerrors
    yield
  File "C:\Users\DELL\AppData\Local\Programs\Python\Python313\Lib\site-packages\rest_framework\request.py", line 232, in user
    self._authenticate()
    ~~~~~~~~~~~~~~~~~~^^
  File "C:\Users\DELL\AppData\Local\Programs\Python\Python313\Lib\site-packages\rest_framework\request.py", line 385, in _authenticate
    user_auth_tuple = authenticator.authenticate(self)
  File "C:\Users\DELL\Desktop\projects\offline_voting_system\backend\accounts\auth.py", line 8, in authenticate
    token = auth_header.lower().split(' ')[1]
            ^^^^^^^^^^^^^^^^^
AttributeError: 'NoneType' object has no attribute 'lower'

During handling of the above exception, another exception occurred:

Traceback (most recent call last):
  File "C:\Users\DELL\AppData\Local\Programs\Python\Python313\Lib\site-packages\django\core\handlers\exception.py", line 55, in inner
    response = get_response(request)
  File "C:\Users\DELL\AppData\Local\Programs\Python\Python313\Lib\site-packages\django\core\handlers\base.py", line 197, in _get_response
    response = wrapped_callback(request, *callback_args, **callback_kwargs)
  File "C:\Users\DELL\AppData\Local\Programs\Python\Python313\Lib\site-packages\django\views\decorators\csrf.py", line 65, in _view_wrapper
    return view_func(request, *args, **kwargs)
  File "C:\Users\DELL\AppData\Local\Programs\Python\Python313\Lib\site-packages\django\views\generic\base.py", line 105, in view
    return self.dispatch(request, *args, **kwargs)
           ~~~~~~~~~~~~~^^^^^^^^^^^^^^^^^^^^^^^^^^
  File "C:\Users\DELL\AppData\Local\Programs\Python\Python313\Lib\site-packages\rest_framework\views.py", line 515, in dispatch
    response = self.handle_exception(exc)
  File "C:\Users\DELL\AppData\Local\Programs\Python\Python313\Lib\site-packages\rest_framework\views.py", line 475, in handle_exception
    self.raise_uncaught_exception(exc)
    ~~~~~~~~~~~~~~~~~~~~~~~~~~~~~^^^^^
  File "C:\Users\DELL\AppData\Local\Programs\Python\Python313\Lib\site-packages\rest_framework\views.py", line 486, in raise_uncaught_exception
    raise exc
  File "C:\Users\DELL\AppData\Local\Programs\Python\Python313\Lib\site-packages\rest_framework\views.py", line 503, in dispatch
    self.initial(request, *args, **kwargs)
    ~~~~~~~~~~~~^^^^^^^^^^^^^^^^^^^^^^^^^^
  File "C:\Users\DELL\AppData\Local\Programs\Python\Python313\Lib\site-packages\rest_framework\views.py", line 420, in initial
    self.perform_authentication(request)
    ~~~~~~~~~~~~~~~~~~~~~~~~~~~^^^^^^^^^
  File "C:\Users\DELL\AppData\Local\Programs\Python\Python313\Lib\site-packages\rest_framework\views.py", line 330, in perform_authentication
    request.user
  File "C:\Users\DELL\AppData\Local\Programs\Python\Python313\Lib\site-packages\rest_framework\request.py", line 231, in user
    with wrap_attributeerrors():
         ~~~~~~~~~~~~~~~~~~~~^^
  File "C:\Users\DELL\AppData\Local\Programs\Python\Python313\Lib\contextlib.py", line 162, in __exit__
    self.gen.throw(value)
    ~~~~~~~~~~~~~~^^^^^^^
  File "C:\Users\DELL\AppData\Local\Programs\Python\Python313\Lib\site-packages\rest_framework\request.py", line 78, in wrap_attributeerrors
    raise exc.with_traceback(info[2])
  File "C:\Users\DELL\AppData\Local\Programs\Python\Python313\Lib\site-packages\rest_framework\request.py", line 74, in wrap_attributeerrors
    yield
  File "C:\Users\DELL\AppData\Local\Programs\Python\Python313\Lib\site-packages\rest_framework\request.py", line 232, in user
    self._authenticate()
    ~~~~~~~~~~~~~~~~~~^^
  File "C:\Users\DELL\AppData\Local\Programs\Python\Python313\Lib\site-packages\rest_framework\request.py", line 385, in _authenticate
    user_auth_tuple = authenticator.authenticate(self)
  File "C:\Users\DELL\Desktop\projects\offline_voting_system\backend\accounts\auth.py", line 8, in authenticate
    token = auth_header.lower().split(' ')[1]
            ^^^^^^^^^^^^^^^^^
rest_framework.request.WrappedAttributeError: 'NoneType' object has no attribute 'lower'
ERROR 2025-08-30 13:03:14,156 log 11612 10272 Internal Server Error: /api/auth/login/
Traceback (most recent call last):
  File "C:\Users\DELL\AppData\Local\Programs\Python\Python313\Lib\site-packages\rest_framework\request.py", line 74, in wrap_attributeerrors
    yield
  File "C:\Users\DELL\AppData\Local\Programs\Python\Python313\Lib\site-packages\rest_framework\request.py", line 232, in user
    self._authenticate()
    ~~~~~~~~~~~~~~~~~~^^
  File "C:\Users\DELL\AppData\Local\Programs\Python\Python313\Lib\site-packages\rest_framework\request.py", line 385, in _authenticate
    user_auth_tuple = authenticator.authenticate(self)
  File "C:\Users\DELL\Desktop\projects\offline_voting_system\backend\accounts\auth.py", line 8, in authenticate
    token = auth_header.lower().split(' ')[1]
            ^^^^^^^^^^^^^^^^^
AttributeError: 'NoneType' object has no attribute 'lower'

During handling of the above exception, another exception occurred:

Traceback (most recent call last):
  File "C:\Users\DELL\AppData\Local\Programs\Python\Python313\Lib\site-packages\django\core\handlers\exception.py", line 55, in inner
    response = get_response(request)
  File "C:\Users\DELL\AppData\Local\Programs\Python\Python313\Lib\site-packages\django\core\handlers\base.py", line 197, in _get_response
    response = wrapped_callback(request, *callback_args, **callback_kwargs)
  File "C:\Users\DELL\AppData\Local\Programs\Python\Python313\Lib\site-packages\django\views\decorators\csrf.py", line 65, in _view_wrapper
    return view_func(request, *args, **kwargs)
  File "C:\Users\DELL\AppData\Local\Programs\Python\Python313\Lib\site-packages\django\views\generic\base.py", line 105, in view
    return self.dispatch(request, *args, **kwargs)
           ~~~~~~~~~~~~~^^^^^^^^^^^^^^^^^^^^^^^^^^
  File "C:\Users\DELL\AppData\Local\Programs\Python\Python313\Lib\site-packages\rest_framework\views.py", line 515, in dispatch
    response = self.handle_exception(exc)
  File "C:\Users\DELL\AppData\Local\Programs\Python\Python313\Lib\site-packages\rest_framework\views.py", line 475, in handle_exception
    self.raise_uncaught_exception(exc)
    ~~~~~~~~~~~~~~~~~~~~~~~~~~~~~^^^^^
  File "C:\Users\DELL\AppData\Local\Programs\Python\Python313\Lib\site-packages\rest_framework\views.py", line 486, in raise_uncaught_exception
    raise exc
  File "C:\Users\DELL\AppData\Local\Programs\Python\Python313\Lib\site-packages\rest_framework\views.py", line 503, in dispatch
    self.initial(request, *args, **kwargs)
    ~~~~~~~~~~~~^^^^^^^^^^^^^^^^^^^^^^^^^^
  File "C:\Users\DELL\AppData\Local\Programs\Python\Python313\Lib\site-packages\rest_framework\views.py", line 420, in initial
    self.perform_authentication(request)
    ~~~~~~~~~~~~~~~~~~~~~~~~~~~^^^^^^^^^
  File "C:\Users\DELL\AppData\Local\Programs\Python\Python313\Lib\site-packages\rest_framework\views.py", line 330, in perform_authentication
    request.user
  File "C:\Users\DELL\AppData\Local\Programs\Python\Python313\Lib\site-packages\rest_framework\request.py", line 231, in user
    with wrap_attributeerrors():
         ~~~~~~~~~~~~~~~~~~~~^^
  File "C:\Users\DELL\AppData\Local\Programs\Python\Python313\Lib\contextlib.py", line 162, in __exit__
    self.gen.throw(value)
    ~~~~~~~~~~~~~~^^^^^^^
  File "C:\Users\DELL\AppData\Local\Programs\Python\Python313\Lib\site-packages\rest_framework\request.py", line 78, in wrap_attributeerrors
    raise exc.with_traceback(info[2])
  File "C:\Users\DELL\AppData\Local\Programs\Python\Python313\Lib\site-packages\rest_framework\request.py", line 74, in wrap_attributeerrors
    yield
  File "C:\Users\DELL\AppData\Local\Programs\Python\Python313\Lib\site-packages\rest_framework\request.py", line 232, in user
    self._authenticate()
    ~~~~~~~~~~~~~~~~~~^^
  File "C:\Users\DELL\AppData\Local\Programs\Python\Python313\Lib\site-packages\rest_framework\request.py", line 385, in _authenticate
    user_auth_tuple = authenticator.authenticate(self)
  File "C:\Users\DELL\Desktop\projects\offline_voting_system\backend\accounts\auth.py", line 8, in authenticate
    token = auth_header.lower().split(' ')[1]
            ^^^^^^^^^^^^^^^^^
rest_framework.request.WrappedAttributeError: 'NoneType' object has no attribute 'lower'
ERROR 2025-08-30 13:03:20,940 log 11612 10272 Internal Server Error: /api/auth/login/
Traceback (most recent call last):
  File "C:\Users\DELL\AppData\Local\Programs\Python\Python313\Lib\site-packages\rest_framework\request.py", line 74, in wrap_attributeerrors
    yield
  File "C:\Users\DELL\AppData\Local\Programs\Python\Python313\Lib\site-packages\rest_framework\request.py", line 232, in user
    self._authenticate()
    ~~~~~~~~~~~~~~~~~~^^
  File "C:\Users\DELL\AppData\Local\Programs\Python\Python313\Lib\site-packages\rest_framework\request.py", line 385, in _authenticate
    user_auth_tuple = authenticator.authenticate(self)
  File "C:\Users\DELL\Desktop\projects\offline_voting_system\backend\accounts\auth.py", line 8, in authenticate
    token = auth_header.lower().split(' ')[1]
            ^^^^^^^^^^^^^^^^^
AttributeError: 'NoneType' object has no attribute 'lower'

During handling of the above exception, another exception occurred:

Traceback (most recent call last):
  File "C:\Users\DELL\AppData\Local\Programs\Python\Python313\Lib\site-packages\django\core\handlers\exception.py", line 55, in inner
    response = get_response(request)
  File "C:\Users\DELL\AppData\Local\Programs\Python\Python313\Lib\site-packages\django\core\handlers\base.py", line 197, in _get_response
    response = wrapped_callback(request, *callback_args, **callback_kwargs)
  File "C:\Users\DELL\AppData\Local\Programs\Python\Python313\Lib\site-packages\django\views\decorators\csrf.py", line 65, in _view_wrapper
    return view_func(request, *args, **kwargs)
  File "C:\Users\DELL\AppData\Local\Programs\Python\Python313\Lib\site-packages\django\views\generic\base.py", line 105, in view
    return self.dispatch(request, *args, **kwargs)
           ~~~~~~~~~~~~~^^^^^^^^^^^^^^^^^^^^^^^^^^
  File "C:\Users\DELL\AppData\Local\Programs\Python\Python313\Lib\site-packages\rest_framework\views.py", line 515, in dispatch
    response = self.handle_exception(exc)
  File "C:\Users\DELL\AppData\Local\Programs\Python\Python313\Lib\site-packages\rest_framework\views.py", line 475, in handle_exception
    self.raise_uncaught_exception(exc)
    ~~~~~~~~~~~~~~~~~~~~~~~~~~~~~^^^^^
  File "C:\Users\DELL\AppData\Local\Programs\Python\Python313\Lib\site-packages\rest_framework\views.py", line 486, in raise_uncaught_exception
    raise exc
  File "C:\Users\DELL\AppData\Local\Programs\Python\Python313\Lib\site-packages\rest_framework\views.py", line 503, in dispatch
    self.initial(request, *args, **kwargs)
    ~~~~~~~~~~~~^^^^^^^^^^^^^^^^^^^^^^^^^^
  File "C:\Users\DELL\AppData\Local\Programs\Python\Python313\Lib\site-packages\rest_framework\views.py", line 420, in initial
    self.perform_authentication(request)
    ~~~~~~~~~~~~~~~~~~~~~~~~~~~^^^^^^^^^
  File "C:\Users\DELL\AppData\Local\Programs\Python\Python313\Lib\site-packages\rest_framework\views.py", line 330, in perform_authentication
    request.user
  File "C:\Users\DELL\AppData\Local\Programs\Python\Python313\Lib\site-packages\rest_framework\request.py", line 231, in user
    with wrap_attributeerrors():
         ~~~~~~~~~~~~~~~~~~~~^^
  File "C:\Users\DELL\AppData\Local\Programs\Python\Python313\Lib\contextlib.py", line 162, in __exit__
    self.gen.throw(value)
    ~~~~~~~~~~~~~~^^^^^^^
  File "C:\Users\DELL\AppData\Local\Programs\Python\Python313\Lib\site-packages\rest_framework\request.py", line 78, in wrap_attributeerrors
    raise exc.with_traceback(info[2])
  File "C:\Users\DELL\AppData\Local\Programs\Python\Python313\Lib\site-packages\rest_framework\request.py", line 74, in wrap_attributeerrors
    yield
  File "C:\Users\DELL\AppData\Local\Programs\Python\Python313\Lib\site-packages\rest_framework\request.py", line 232, in user
    self._authenticate()
    ~~~~~~~~~~~~~~~~~~^^
  File "C:\Users\DELL\AppData\Local\Programs\Python\Python313\Lib\site-packages\rest_framework\request.py", line 385, in _authenticate
    user_auth_tuple = authenticator.authenticate(self)
  File "C:\Users\DELL\Desktop\projects\offline_voting_system\backend\accounts\auth.py", line 8, in authenticate
    token = auth_header.lower().split(' ')[1]
            ^^^^^^^^^^^^^^^^^
rest_framework.request.WrappedAttributeError: 'NoneType' object has no attribute 'lower'
ERROR 2025-08-30 13:03:43,258 log 11612 11884 Internal Server Error: /api/auth/login/
Traceback (most recent call last):
  File "C:\Users\DELL\AppData\Local\Programs\Python\Python313\Lib\site-packages\rest_framework\request.py", line 74, in wrap_attributeerrors
    yield
  File "C:\Users\DELL\AppData\Local\Programs\Python\Python313\Lib\site-packages\rest_framework\request.py", line 232, in user
    self._authenticate()
    ~~~~~~~~~~~~~~~~~~^^
  File "C:\Users\DELL\AppData\Local\Programs\Python\Python313\Lib\site-packages\rest_framework\request.py", line 385, in _authenticate
    user_auth_tuple = authenticator.authenticate(self)
  File "C:\Users\DELL\Desktop\projects\offline_voting_system\backend\accounts\auth.py", line 8, in authenticate
    token = auth_header.lower().split(' ')[1]
            ^^^^^^^^^^^^^^^^^
AttributeError: 'NoneType' object has no attribute 'lower'

During handling of the above exception, another exception occurred:

Traceback (most recent call last):
  File "C:\Users\DELL\AppData\Local\Programs\Python\Python313\Lib\site-packages\django\core\handlers\exception.py", line 55, in inner
    response = get_response(request)
  File "C:\Users\DELL\AppData\Local\Programs\Python\Python313\Lib\site-packages\django\core\handlers\base.py", line 197, in _get_response
    response = wrapped_callback(request, *callback_args, **callback_kwargs)
  File "C:\Users\DELL\AppData\Local\Programs\Python\Python313\Lib\site-packages\django\views\decorators\csrf.py", line 65, in _view_wrapper
    return view_func(request, *args, **kwargs)
  File "C:\Users\DELL\AppData\Local\Programs\Python\Python313\Lib\site-packages\django\views\generic\base.py", line 105, in view
    return self.dispatch(request, *args, **kwargs)
           ~~~~~~~~~~~~~^^^^^^^^^^^^^^^^^^^^^^^^^^
  File "C:\Users\DELL\AppData\Local\Programs\Python\Python313\Lib\site-packages\rest_framework\views.py", line 515, in dispatch
    response = self.handle_exception(exc)
  File "C:\Users\DELL\AppData\Local\Programs\Python\Python313\Lib\site-packages\rest_framework\views.py", line 475, in handle_exception
    self.raise_uncaught_exception(exc)
    ~~~~~~~~~~~~~~~~~~~~~~~~~~~~~^^^^^
  File "C:\Users\DELL\AppData\Local\Programs\Python\Python313\Lib\site-packages\rest_framework\views.py", line 486, in raise_uncaught_exception
    raise exc
  File "C:\Users\DELL\AppData\Local\Programs\Python\Python313\Lib\site-packages\rest_framework\views.py", line 503, in dispatch
    self.initial(request, *args, **kwargs)
    ~~~~~~~~~~~~^^^^^^^^^^^^^^^^^^^^^^^^^^
  File "C:\Users\DELL\AppData\Local\Programs\Python\Python313\Lib\site-packages\rest_framework\views.py", line 420, in initial
    self.perform_authentication(request)
    ~~~~~~~~~~~~~~~~~~~~~~~~~~~^^^^^^^^^
  File "C:\Users\DELL\AppData\Local\Programs\Python\Python313\Lib\site-packages\rest_framework\views.py", line 330, in perform_authentication
    request.user
  File "C:\Users\DELL\AppData\Local\Programs\Python\Python313\Lib\site-packages\rest_framework\request.py", line 231, in user
    with wrap_attributeerrors():
         ~~~~~~~~~~~~~~~~~~~~^^
  File "C:\Users\DELL\AppData\Local\Programs\Python\Python313\Lib\contextlib.py", line 162, in __exit__
    self.gen.throw(value)
    ~~~~~~~~~~~~~~^^^^^^^
  File "C:\Users\DELL\AppData\Local\Programs\Python\Python313\Lib\site-packages\rest_framework\request.py", line 78, in wrap_attributeerrors
    raise exc.with_traceback(info[2])
  File "C:\Users\DELL\AppData\Local\Programs\Python\Python313\Lib\site-packages\rest_framework\request.py", line 74, in wrap_attributeerrors
    yield
  File "C:\Users\DELL\AppData\Local\Programs\Python\Python313\Lib\site-packages\rest_framework\request.py", line 232, in user
    self._authenticate()
    ~~~~~~~~~~~~~~~~~~^^
  File "C:\Users\DELL\AppData\Local\Programs\Python\Python313\Lib\site-packages\rest_framework\request.py", line 385, in _authenticate
    user_auth_tuple = authenticator.authenticate(self)
  File "C:\Users\DELL\Desktop\projects\offline_voting_system\backend\accounts\auth.py", line 8, in authenticate
    token = auth_header.lower().split(' ')[1]
            ^^^^^^^^^^^^^^^^^
rest_framework.request.WrappedAttributeError: 'NoneType' object has no attribute 'lower'
ERROR 2025-08-30 13:32:52,798 log 11612 12780 Internal Server Error: /api/auth/login/
Traceback (most recent call last):
  File "C:\Users\DELL\AppData\Local\Programs\Python\Python313\Lib\site-packages\rest_framework\request.py", line 74, in wrap_attributeerrors
    yield
  File "C:\Users\DELL\AppData\Local\Programs\Python\Python313\Lib\site-packages\rest_framework\request.py", line 232, in user
    self._authenticate()
    ~~~~~~~~~~~~~~~~~~^^
  File "C:\Users\DELL\AppData\Local\Programs\Python\Python313\Lib\site-packages\rest_framework\request.py", line 385, in _authenticate
    user_auth_tuple = authenticator.authenticate(self)
  File "C:\Users\DELL\Desktop\projects\offline_voting_system\backend\accounts\auth.py", line 8, in authenticate
    token = auth_header.lower().split(' ')[1]
            ^^^^^^^^^^^^^^^^^
AttributeError: 'NoneType' object has no attribute 'lower'

During handling of the above exception, another exception occurred:

Traceback (most recent call last):
  File "C:\Users\DELL\AppData\Local\Programs\Python\Python313\Lib\site-packages\django\core\handlers\exception.py", line 55, in inner
    response = get_response(request)
  File "C:\Users\DELL\AppData\Local\Programs\Python\Python313\Lib\site-packages\django\core\handlers\base.py", line 197, in _get_response
    response = wrapped_callback(request, *callback_args, **callback_kwargs)
  File "C:\Users\DELL\AppData\Local\Programs\Python\Python313\Lib\site-packages\django\views\decorators\csrf.py", line 65, in _view_wrapper
    return view_func(request, *args, **kwargs)
  File "C:\Users\DELL\AppData\Local\Programs\Python\Python313\Lib\site-packages\django\views\generic\base.py", line 105, in view
    return self.dispatch(request, *args, **kwargs)
           ~~~~~~~~~~~~~^^^^^^^^^^^^^^^^^^^^^^^^^^
  File "C:\Users\DELL\AppData\Local\Programs\Python\Python313\Lib\site-packages\rest_framework\views.py", line 515, in dispatch
    response = self.handle_exception(exc)
  File "C:\Users\DELL\AppData\Local\Programs\Python\Python313\Lib\site-packages\rest_framework\views.py", line 475, in handle_exception
    self.raise_uncaught_exception(exc)
    ~~~~~~~~~~~~~~~~~~~~~~~~~~~~~^^^^^
  File "C:\Users\DELL\AppData\Local\Programs\Python\Python313\Lib\site-packages\rest_framework\views.py", line 486, in raise_uncaught_exception
    raise exc
  File "C:\Users\DELL\AppData\Local\Programs\Python\Python313\Lib\site-packages\rest_framework\views.py", line 503, in dispatch
    self.initial(request, *args, **kwargs)
    ~~~~~~~~~~~~^^^^^^^^^^^^^^^^^^^^^^^^^^
  File "C:\Users\DELL\AppData\Local\Programs\Python\Python313\Lib\site-packages\rest_framework\views.py", line 420, in initial
    self.perform_authentication(request)
    ~~~~~~~~~~~~~~~~~~~~~~~~~~~^^^^^^^^^
  File "C:\Users\DELL\AppData\Local\Programs\Python\Python313\Lib\site-packages\rest_framework\views.py", line 330, in perform_authentication
    request.user
  File "C:\Users\DELL\AppData\Local\Programs\Python\Python313\Lib\site-packages\rest_framework\request.py", line 231, in user
    with wrap_attributeerrors():
         ~~~~~~~~~~~~~~~~~~~~^^
  File "C:\Users\DELL\AppData\Local\Programs\Python\Python313\Lib\contextlib.py", line 162, in __exit__
    self.gen.throw(value)
    ~~~~~~~~~~~~~~^^^^^^^
  File "C:\Users\DELL\AppData\Local\Programs\Python\Python313\Lib\site-packages\rest_framework\request.py", line 78, in wrap_attributeerrors
    raise exc.with_traceback(info[2])
  File "C:\Users\DELL\AppData\Local\Programs\Python\Python313\Lib\site-packages\rest_framework\request.py", line 74, in wrap_attributeerrors
    yield
  File "C:\Users\DELL\AppData\Local\Programs\Python\Python313\Lib\site-packages\rest_framework\request.py", line 232, in user
    self._authenticate()
    ~~~~~~~~~~~~~~~~~~^^
  File "C:\Users\DELL\AppData\Local\Programs\Python\Python313\Lib\site-packages\rest_framework\request.py", line 385, in _authenticate
    user_auth_tuple = authenticator.authenticate(self)
  File "C:\Users\DELL\Desktop\projects\offline_voting_system\backend\accounts\auth.py", line 8, in authenticate
    token = auth_header.lower().split(' ')[1]
            ^^^^^^^^^^^^^^^^^
rest_framework.request.WrappedAttributeError: 'NoneType' object has no attribute 'lower'
ERROR 2025-08-30 13:33:03,420 log 11612 15308 Internal Server Error: /api/elections/elections/
Traceback (most recent call last):
  File "C:\Users\DELL\AppData\Local\Programs\Python\Python313\Lib\site-packages\rest_framework\request.py", line 74, in wrap_attributeerrors
    yield
  File "C:\Users\DELL\AppData\Local\Programs\Python\Python313\Lib\site-packages\rest_framework\request.py", line 232, in user
    self._authenticate()
    ~~~~~~~~~~~~~~~~~~^^
  File "C:\Users\DELL\AppData\Local\Programs\Python\Python313\Lib\site-packages\rest_framework\request.py", line 385, in _authenticate
    user_auth_tuple = authenticator.authenticate(self)
  File "C:\Users\DELL\Desktop\projects\offline_voting_system\backend\accounts\auth.py", line 8, in authenticate
    token = auth_header.lower().split(' ')[1]
            ^^^^^^^^^^^^^^^^^
AttributeError: 'NoneType' object has no attribute 'lower'

During handling of the above exception, another exception occurred:

Traceback (most recent call last):
  File "C:\Users\DELL\AppData\Local\Programs\Python\Python313\Lib\site-packages\django\core\handlers\exception.py", line 55, in inner
    response = get_response(request)
  File "C:\Users\DELL\AppData\Local\Programs\Python\Python313\Lib\site-packages\django\core\handlers\base.py", line 197, in _get_response
    response = wrapped_callback(request, *callback_args, **callback_kwargs)
  File "C:\Users\DELL\AppData\Local\Programs\Python\Python313\Lib\site-packages\django\views\decorators\csrf.py", line 65, in _view_wrapper
    return view_func(request, *args, **kwargs)
  File "C:\Users\DELL\AppData\Local\Programs\Python\Python313\Lib\site-packages\rest_framework\viewsets.py", line 125, in view
    return self.dispatch(request, *args, **kwargs)
           ~~~~~~~~~~~~~^^^^^^^^^^^^^^^^^^^^^^^^^^
  File "C:\Users\DELL\AppData\Local\Programs\Python\Python313\Lib\site-packages\rest_framework\views.py", line 515, in dispatch
    response = self.handle_exception(exc)
  File "C:\Users\DELL\AppData\Local\Programs\Python\Python313\Lib\site-packages\rest_framework\views.py", line 475, in handle_exception
    self.raise_uncaught_exception(exc)
    ~~~~~~~~~~~~~~~~~~~~~~~~~~~~~^^^^^
  File "C:\Users\DELL\AppData\Local\Programs\Python\Python313\Lib\site-packages\rest_framework\views.py", line 486, in raise_uncaught_exception
    raise exc
  File "C:\Users\DELL\AppData\Local\Programs\Python\Python313\Lib\site-packages\rest_framework\views.py", line 503, in dispatch
    self.initial(request, *args, **kwargs)
    ~~~~~~~~~~~~^^^^^^^^^^^^^^^^^^^^^^^^^^
  File "C:\Users\DELL\AppData\Local\Programs\Python\Python313\Lib\site-packages\rest_framework\views.py", line 420, in initial
    self.perform_authentication(request)
    ~~~~~~~~~~~~~~~~~~~~~~~~~~~^^^^^^^^^
  File "C:\Users\DELL\AppData\Local\Programs\Python\Python313\Lib\site-packages\rest_framework\views.py", line 330, in perform_authentication
    request.user
  File "C:\Users\DELL\AppData\Local\Programs\Python\Python313\Lib\site-packages\rest_framework\request.py", line 231, in user
    with wrap_attributeerrors():
         ~~~~~~~~~~~~~~~~~~~~^^
  File "C:\Users\DELL\AppData\Local\Programs\Python\Python313\Lib\contextlib.py", line 162, in __exit__
    self.gen.throw(value)
    ~~~~~~~~~~~~~~^^^^^^^
  File "C:\Users\DELL\AppData\Local\Programs\Python\Python313\Lib\site-packages\rest_framework\request.py", line 78, in wrap_attributeerrors
    raise exc.with_traceback(info[2])
  File "C:\Users\DELL\AppData\Local\Programs\Python\Python313\Lib\site-packages\rest_framework\request.py", line 74, in wrap_attributeerrors
    yield
  File "C:\Users\DELL\AppData\Local\Programs\Python\Python313\Lib\site-packages\rest_framework\request.py", line 232, in user
    self._authenticate()
    ~~~~~~~~~~~~~~~~~~^^
  File "C:\Users\DELL\AppData\Local\Programs\Python\Python313\Lib\site-packages\rest_framework\request.py", line 385, in _authenticate
    user_auth_tuple = authenticator.authenticate(self)
  File "C:\Users\DELL\Desktop\projects\offline_voting_system\backend\accounts\auth.py", line 8, in authenticate
    token = auth_header.lower().split(' ')[1]
            ^^^^^^^^^^^^^^^^^
rest_framework.request.WrappedAttributeError: 'NoneType' object has no attribute 'lower'
ERROR 2025-08-30 13:33:03,688 log 11612 12504 Internal Server Error: /api/elections/elections/
Traceback (most recent call last):
  File "C:\Users\DELL\AppData\Local\Programs\Python\Python313\Lib\site-packages\rest_framework\request.py", line 74, in wrap_attributeerrors
    yield
  File "C:\Users\DELL\AppData\Local\Programs\Python\Python313\Lib\site-packages\rest_framework\request.py", line 232, in user
    self._authenticate()
    ~~~~~~~~~~~~~~~~~~^^
  File "C:\Users\DELL\AppData\Local\Programs\Python\Python313\Lib\site-packages\rest_framework\request.py", line 385, in _authenticate
    user_auth_tuple = authenticator.authenticate(self)
  File "C:\Users\DELL\Desktop\projects\offline_voting_system\backend\accounts\auth.py", line 8, in authenticate
    token = auth_header.lower().split(' ')[1]
            ^^^^^^^^^^^^^^^^^
AttributeError: 'NoneType' object has no attribute 'lower'

During handling of the above exception, another exception occurred:

Traceback (most recent call last):
  File "C:\Users\DELL\AppData\Local\Programs\Python\Python313\Lib\site-packages\django\core\handlers\exception.py", line 55, in inner
    response = get_response(request)
  File "C:\Users\DELL\AppData\Local\Programs\Python\Python313\Lib\site-packages\django\core\handlers\base.py", line 197, in _get_response
    response = wrapped_callback(request, *callback_args, **callback_kwargs)
  File "C:\Users\DELL\AppData\Local\Programs\Python\Python313\Lib\site-packages\django\views\decorators\csrf.py", line 65, in _view_wrapper
    return view_func(request, *args, **kwargs)
  File "C:\Users\DELL\AppData\Local\Programs\Python\Python313\Lib\site-packages\rest_framework\viewsets.py", line 125, in view
    return self.dispatch(request, *args, **kwargs)
           ~~~~~~~~~~~~~^^^^^^^^^^^^^^^^^^^^^^^^^^
  File "C:\Users\DELL\AppData\Local\Programs\Python\Python313\Lib\site-packages\rest_framework\views.py", line 515, in dispatch
    response = self.handle_exception(exc)
  File "C:\Users\DELL\AppData\Local\Programs\Python\Python313\Lib\site-packages\rest_framework\views.py", line 475, in handle_exception
    self.raise_uncaught_exception(exc)
    ~~~~~~~~~~~~~~~~~~~~~~~~~~~~~^^^^^
  File "C:\Users\DELL\AppData\Local\Programs\Python\Python313\Lib\site-packages\rest_framework\views.py", line 486, in raise_uncaught_exception
    raise exc
  File "C:\Users\DELL\AppData\Local\Programs\Python\Python313\Lib\site-packages\rest_framework\views.py", line 503, in dispatch
    self.initial(request, *args, **kwargs)
    ~~~~~~~~~~~~^^^^^^^^^^^^^^^^^^^^^^^^^^
  File "C:\Users\DELL\AppData\Local\Programs\Python\Python313\Lib\site-packages\rest_framework\views.py", line 420, in initial
    self.perform_authentication(request)
    ~~~~~~~~~~~~~~~~~~~~~~~~~~~^^^^^^^^^
  File "C:\Users\DELL\AppData\Local\Programs\Python\Python313\Lib\site-packages\rest_framework\views.py", line 330, in perform_authentication
    request.user
  File "C:\Users\DELL\AppData\Local\Programs\Python\Python313\Lib\site-packages\rest_framework\request.py", line 231, in user
    with wrap_attributeerrors():
         ~~~~~~~~~~~~~~~~~~~~^^
  File "C:\Users\DELL\AppData\Local\Programs\Python\Python313\Lib\contextlib.py", line 162, in __exit__
    self.gen.throw(value)
    ~~~~~~~~~~~~~~^^^^^^^
  File "C:\Users\DELL\AppData\Local\Programs\Python\Python313\Lib\site-packages\rest_framework\request.py", line 78, in wrap_attributeerrors
    raise exc.with_traceback(info[2])
  File "C:\Users\DELL\AppData\Local\Programs\Python\Python313\Lib\site-packages\rest_framework\request.py", line 74, in wrap_attributeerrors
    yield
  File "C:\Users\DELL\AppData\Local\Programs\Python\Python313\Lib\site-packages\rest_framework\request.py", line 232, in user
    self._authenticate()
    ~~~~~~~~~~~~~~~~~~^^
  File "C:\Users\DELL\AppData\Local\Programs\Python\Python313\Lib\site-packages\rest_framework\request.py", line 385, in _authenticate
    user_auth_tuple = authenticator.authenticate(self)
  File "C:\Users\DELL\Desktop\projects\offline_voting_system\backend\accounts\auth.py", line 8, in authenticate
    token = auth_header.lower().split(' ')[1]
            ^^^^^^^^^^^^^^^^^
rest_framework.request.WrappedAttributeError: 'NoneType' object has no attribute 'lower'
ERROR 2025-08-30 14:08:17,819 log 2396 8616 Internal Server Error: /api/auth/voter_login/
Traceback (most recent call last):
  File "C:\Users\DELL\AppData\Local\Programs\Python\Python313\Lib\site-packages\django\core\handlers\exception.py", line 55, in inner
    response = get_response(request)
  File "C:\Users\DELL\AppData\Local\Programs\Python\Python313\Lib\site-packages\django\core\handlers\base.py", line 197, in _get_response
    response = wrapped_callback(request, *callback_args, **callback_kwargs)
  File "C:\Users\DELL\AppData\Local\Programs\Python\Python313\Lib\site-packages\django\views\decorators\csrf.py", line 65, in _view_wrapper
    return view_func(request, *args, **kwargs)
  File "C:\Users\DELL\AppData\Local\Programs\Python\Python313\Lib\site-packages\django\views\generic\base.py", line 105, in view
    return self.dispatch(request, *args, **kwargs)
           ~~~~~~~~~~~~~^^^^^^^^^^^^^^^^^^^^^^^^^^
  File "C:\Users\DELL\AppData\Local\Programs\Python\Python313\Lib\site-packages\rest_framework\views.py", line 515, in dispatch
    response = self.handle_exception(exc)
  File "C:\Users\DELL\AppData\Local\Programs\Python\Python313\Lib\site-packages\rest_framework\views.py", line 475, in handle_exception
    self.raise_uncaught_exception(exc)
    ~~~~~~~~~~~~~~~~~~~~~~~~~~~~~^^^^^
  File "C:\Users\DELL\AppData\Local\Programs\Python\Python313\Lib\site-packages\rest_framework\views.py", line 486, in raise_uncaught_exception
    raise exc
  File "C:\Users\DELL\AppData\Local\Programs\Python\Python313\Lib\site-packages\rest_framework\views.py", line 512, in dispatch
    response = handler(request, *args, **kwargs)
  File "C:\Users\DELL\Desktop\projects\offline_voting_system\backend\accounts\views.py", line 63, in post
    has_voted = Vote.objects.filter(voter=voter, election=voter.election).exists()
                ~~~~~~~~~~~~~~~~~~~^^^^^^^^^^^^^^^^^^^^^^^^^^^^^^^^^^^^^^
  File "C:\Users\DELL\AppData\Local\Programs\Python\Python313\Lib\site-packages\django\db\models\manager.py", line 87, in manager_method
    return getattr(self.get_queryset(), name)(*args, **kwargs)
           ~~~~~~~~~~~~~~~~~~~~~~~~~~~~~~~~~~^^^^^^^^^^^^^^^^^
  File "C:\Users\DELL\AppData\Local\Programs\Python\Python313\Lib\site-packages\django\db\models\query.py", line 1493, in filter
    return self._filter_or_exclude(False, args, kwargs)
           ~~~~~~~~~~~~~~~~~~~~~~~^^^^^^^^^^^^^^^^^^^^^
  File "C:\Users\DELL\AppData\Local\Programs\Python\Python313\Lib\site-packages\django\db\models\query.py", line 1511, in _filter_or_exclude
    clone._filter_or_exclude_inplace(negate, args, kwargs)
    ~~~~~~~~~~~~~~~~~~~~~~~~~~~~~~~~^^^^^^^^^^^^^^^^^^^^^^
  File "C:\Users\DELL\AppData\Local\Programs\Python\Python313\Lib\site-packages\django\db\models\query.py", line 1518, in _filter_or_exclude_inplace
    self._query.add_q(Q(*args, **kwargs))
    ~~~~~~~~~~~~~~~~~^^^^^^^^^^^^^^^^^^^^
  File "C:\Users\DELL\AppData\Local\Programs\Python\Python313\Lib\site-packages\django\db\models\sql\query.py", line 1646, in add_q
    clause, _ = self._add_q(q_object, can_reuse)
                ~~~~~~~~~~~^^^^^^^^^^^^^^^^^^^^^
  File "C:\Users\DELL\AppData\Local\Programs\Python\Python313\Lib\site-packages\django\db\models\sql\query.py", line 1678, in _add_q
    child_clause, needed_inner = self.build_filter(
                                 ~~~~~~~~~~~~~~~~~^
        child,
        ^^^^^^
    ...<7 lines>...
        update_join_types=update_join_types,
        ^^^^^^^^^^^^^^^^^^^^^^^^^^^^^^^^^^^^
    )
    ^
  File "C:\Users\DELL\AppData\Local\Programs\Python\Python313\Lib\site-packages\django\db\models\sql\query.py", line 1526, in build_filter
    lookups, parts, reffed_expression = self.solve_lookup_type(arg, summarize)
                                        ~~~~~~~~~~~~~~~~~~~~~~^^^^^^^^^^^^^^^^
  File "C:\Users\DELL\AppData\Local\Programs\Python\Python313\Lib\site-packages\django\db\models\sql\query.py", line 1333, in solve_lookup_type
    _, field, _, lookup_parts = self.names_to_path(lookup_splitted, self.get_meta())
                                ~~~~~~~~~~~~~~~~~~^^^^^^^^^^^^^^^^^^^^^^^^^^^^^^^^^^
  File "C:\Users\DELL\AppData\Local\Programs\Python\Python313\Lib\site-packages\django\db\models\sql\query.py", line 1805, in names_to_path
    raise FieldError(
    ...<2 lines>...
    )
django.core.exceptions.FieldError: Cannot resolve keyword 'voter' into field. Choices are: candidate, candidate_id, election, election_id, portfolio, portfolio_id, skip_vote, vote_id, vote_time
ERROR 2025-08-30 14:18:07,321 log 2396 8976 Internal Server Error: /api/auth/voter_login/
Traceback (most recent call last):
  File "C:\Users\DELL\AppData\Local\Programs\Python\Python313\Lib\site-packages\django\core\handlers\exception.py", line 55, in inner
    response = get_response(request)
  File "C:\Users\DELL\AppData\Local\Programs\Python\Python313\Lib\site-packages\django\core\handlers\base.py", line 197, in _get_response
    response = wrapped_callback(request, *callback_args, **callback_kwargs)
  File "C:\Users\DELL\AppData\Local\Programs\Python\Python313\Lib\site-packages\django\views\decorators\csrf.py", line 65, in _view_wrapper
    return view_func(request, *args, **kwargs)
  File "C:\Users\DELL\AppData\Local\Programs\Python\Python313\Lib\site-packages\django\views\generic\base.py", line 105, in view
    return self.dispatch(request, *args, **kwargs)
           ~~~~~~~~~~~~~^^^^^^^^^^^^^^^^^^^^^^^^^^
  File "C:\Users\DELL\AppData\Local\Programs\Python\Python313\Lib\site-packages\rest_framework\views.py", line 515, in dispatch
    response = self.handle_exception(exc)
  File "C:\Users\DELL\AppData\Local\Programs\Python\Python313\Lib\site-packages\rest_framework\views.py", line 475, in handle_exception
    self.raise_uncaught_exception(exc)
    ~~~~~~~~~~~~~~~~~~~~~~~~~~~~~^^^^^
  File "C:\Users\DELL\AppData\Local\Programs\Python\Python313\Lib\site-packages\rest_framework\views.py", line 486, in raise_uncaught_exception
    raise exc
  File "C:\Users\DELL\AppData\Local\Programs\Python\Python313\Lib\site-packages\rest_framework\views.py", line 512, in dispatch
    response = handler(request, *args, **kwargs)
  File "C:\Users\DELL\Desktop\projects\offline_voting_system\backend\accounts\views.py", line 58, in post
    if not voter.election.is_ongoing:
           ^^^^^
UnboundLocalError: cannot access local variable 'voter' where it is not associated with a value
ERROR 2025-08-30 14:32:21,203 log 12296 13804 Internal Server Error: /api/auth/voter_login/
Traceback (most recent call last):
  File "C:\Users\DELL\AppData\Local\Programs\Python\Python313\Lib\site-packages\django\core\handlers\exception.py", line 55, in inner
    response = get_response(request)
  File "C:\Users\DELL\AppData\Local\Programs\Python\Python313\Lib\site-packages\django\core\handlers\base.py", line 197, in _get_response
    response = wrapped_callback(request, *callback_args, **callback_kwargs)
  File "C:\Users\DELL\AppData\Local\Programs\Python\Python313\Lib\site-packages\django\views\decorators\csrf.py", line 65, in _view_wrapper
    return view_func(request, *args, **kwargs)
  File "C:\Users\DELL\AppData\Local\Programs\Python\Python313\Lib\site-packages\django\views\generic\base.py", line 105, in view
    return self.dispatch(request, *args, **kwargs)
           ~~~~~~~~~~~~~^^^^^^^^^^^^^^^^^^^^^^^^^^
  File "C:\Users\DELL\AppData\Local\Programs\Python\Python313\Lib\site-packages\rest_framework\views.py", line 515, in dispatch
    response = self.handle_exception(exc)
  File "C:\Users\DELL\AppData\Local\Programs\Python\Python313\Lib\site-packages\rest_framework\views.py", line 475, in handle_exception
    self.raise_uncaught_exception(exc)
    ~~~~~~~~~~~~~~~~~~~~~~~~~~~~~^^^^^
  File "C:\Users\DELL\AppData\Local\Programs\Python\Python313\Lib\site-packages\rest_framework\views.py", line 486, in raise_uncaught_exception
    raise exc
  File "C:\Users\DELL\AppData\Local\Programs\Python\Python313\Lib\site-packages\rest_framework\views.py", line 512, in dispatch
    response = handler(request, *args, **kwargs)
  File "C:\Users\DELL\Desktop\projects\offline_voting_system\backend\accounts\views.py", line 58, in post
    if voter.election.only_admin_allowed():
       ^^^^^
UnboundLocalError: cannot access local variable 'voter' where it is not associated with a value
ERROR 2025-08-30 14:32:27,068 log 12296 12856 Internal Server Error: /api/auth/voter_login/
Traceback (most recent call last):
  File "C:\Users\DELL\AppData\Local\Programs\Python\Python313\Lib\site-packages\django\core\handlers\exception.py", line 55, in inner
    response = get_response(request)
  File "C:\Users\DELL\AppData\Local\Programs\Python\Python313\Lib\site-packages\django\core\handlers\base.py", line 197, in _get_response
    response = wrapped_callback(request, *callback_args, **callback_kwargs)
  File "C:\Users\DELL\AppData\Local\Programs\Python\Python313\Lib\site-packages\django\views\decorators\csrf.py", line 65, in _view_wrapper
    return view_func(request, *args, **kwargs)
  File "C:\Users\DELL\AppData\Local\Programs\Python\Python313\Lib\site-packages\django\views\generic\base.py", line 105, in view
    return self.dispatch(request, *args, **kwargs)
           ~~~~~~~~~~~~~^^^^^^^^^^^^^^^^^^^^^^^^^^
  File "C:\Users\DELL\AppData\Local\Programs\Python\Python313\Lib\site-packages\rest_framework\views.py", line 515, in dispatch
    response = self.handle_exception(exc)
  File "C:\Users\DELL\AppData\Local\Programs\Python\Python313\Lib\site-packages\rest_framework\views.py", line 475, in handle_exception
    self.raise_uncaught_exception(exc)
    ~~~~~~~~~~~~~~~~~~~~~~~~~~~~~^^^^^
  File "C:\Users\DELL\AppData\Local\Programs\Python\Python313\Lib\site-packages\rest_framework\views.py", line 486, in raise_uncaught_exception
    raise exc
  File "C:\Users\DELL\AppData\Local\Programs\Python\Python313\Lib\site-packages\rest_framework\views.py", line 512, in dispatch
    response = handler(request, *args, **kwargs)
  File "C:\Users\DELL\Desktop\projects\offline_voting_system\backend\accounts\views.py", line 58, in post
    if voter.election.only_admin_allowed():
       ^^^^^
UnboundLocalError: cannot access local variable 'voter' where it is not associated with a value
ERROR 2025-08-30 14:46:26,058 log 12272 14656 Internal Server Error: /api/auth/voter_login/
Traceback (most recent call last):
  File "C:\Users\DELL\AppData\Local\Programs\Python\Python313\Lib\site-packages\django\core\handlers\exception.py", line 55, in inner
    response = get_response(request)
  File "C:\Users\DELL\AppData\Local\Programs\Python\Python313\Lib\site-packages\django\core\handlers\base.py", line 197, in _get_response
    response = wrapped_callback(request, *callback_args, **callback_kwargs)
  File "C:\Users\DELL\AppData\Local\Programs\Python\Python313\Lib\site-packages\django\views\decorators\csrf.py", line 65, in _view_wrapper
    return view_func(request, *args, **kwargs)
  File "C:\Users\DELL\AppData\Local\Programs\Python\Python313\Lib\site-packages\django\views\generic\base.py", line 105, in view
    return self.dispatch(request, *args, **kwargs)
           ~~~~~~~~~~~~~^^^^^^^^^^^^^^^^^^^^^^^^^^
  File "C:\Users\DELL\AppData\Local\Programs\Python\Python313\Lib\site-packages\rest_framework\views.py", line 515, in dispatch
    response = self.handle_exception(exc)
  File "C:\Users\DELL\AppData\Local\Programs\Python\Python313\Lib\site-packages\rest_framework\views.py", line 475, in handle_exception
    self.raise_uncaught_exception(exc)
    ~~~~~~~~~~~~~~~~~~~~~~~~~~~~~^^^^^
  File "C:\Users\DELL\AppData\Local\Programs\Python\Python313\Lib\site-packages\rest_framework\views.py", line 486, in raise_uncaught_exception
    raise exc
  File "C:\Users\DELL\AppData\Local\Programs\Python\Python313\Lib\site-packages\rest_framework\views.py", line 512, in dispatch
    response = handler(request, *args, **kwargs)
  File "C:\Users\DELL\Desktop\projects\offline_voting_system\backend\accounts\views.py", line 65, in post
    has_voted = Vote.objects.filter(voter=voter, election=voter.election).exists()
                ~~~~~~~~~~~~~~~~~~~^^^^^^^^^^^^^^^^^^^^^^^^^^^^^^^^^^^^^^
  File "C:\Users\DELL\AppData\Local\Programs\Python\Python313\Lib\site-packages\django\db\models\manager.py", line 87, in manager_method
    return getattr(self.get_queryset(), name)(*args, **kwargs)
           ~~~~~~~~~~~~~~~~~~~~~~~~~~~~~~~~~~^^^^^^^^^^^^^^^^^
  File "C:\Users\DELL\AppData\Local\Programs\Python\Python313\Lib\site-packages\django\db\models\query.py", line 1493, in filter
    return self._filter_or_exclude(False, args, kwargs)
           ~~~~~~~~~~~~~~~~~~~~~~~^^^^^^^^^^^^^^^^^^^^^
  File "C:\Users\DELL\AppData\Local\Programs\Python\Python313\Lib\site-packages\django\db\models\query.py", line 1511, in _filter_or_exclude
    clone._filter_or_exclude_inplace(negate, args, kwargs)
    ~~~~~~~~~~~~~~~~~~~~~~~~~~~~~~~~^^^^^^^^^^^^^^^^^^^^^^
  File "C:\Users\DELL\AppData\Local\Programs\Python\Python313\Lib\site-packages\django\db\models\query.py", line 1518, in _filter_or_exclude_inplace
    self._query.add_q(Q(*args, **kwargs))
    ~~~~~~~~~~~~~~~~~^^^^^^^^^^^^^^^^^^^^
  File "C:\Users\DELL\AppData\Local\Programs\Python\Python313\Lib\site-packages\django\db\models\sql\query.py", line 1646, in add_q
    clause, _ = self._add_q(q_object, can_reuse)
                ~~~~~~~~~~~^^^^^^^^^^^^^^^^^^^^^
  File "C:\Users\DELL\AppData\Local\Programs\Python\Python313\Lib\site-packages\django\db\models\sql\query.py", line 1678, in _add_q
    child_clause, needed_inner = self.build_filter(
                                 ~~~~~~~~~~~~~~~~~^
        child,
        ^^^^^^
    ...<7 lines>...
        update_join_types=update_join_types,
        ^^^^^^^^^^^^^^^^^^^^^^^^^^^^^^^^^^^^
    )
    ^
  File "C:\Users\DELL\AppData\Local\Programs\Python\Python313\Lib\site-packages\django\db\models\sql\query.py", line 1526, in build_filter
    lookups, parts, reffed_expression = self.solve_lookup_type(arg, summarize)
                                        ~~~~~~~~~~~~~~~~~~~~~~^^^^^^^^^^^^^^^^
  File "C:\Users\DELL\AppData\Local\Programs\Python\Python313\Lib\site-packages\django\db\models\sql\query.py", line 1333, in solve_lookup_type
    _, field, _, lookup_parts = self.names_to_path(lookup_splitted, self.get_meta())
                                ~~~~~~~~~~~~~~~~~~^^^^^^^^^^^^^^^^^^^^^^^^^^^^^^^^^^
  File "C:\Users\DELL\AppData\Local\Programs\Python\Python313\Lib\site-packages\django\db\models\sql\query.py", line 1805, in names_to_path
    raise FieldError(
    ...<2 lines>...
    )
django.core.exceptions.FieldError: Cannot resolve keyword 'voter' into field. Choices are: candidate, candidate_id, election, election_id, portfolio, portfolio_id, skip_vote, vote_id, vote_time
